Workbook

Sheet __FDSCACHE__
B1: This sheet contains FactSet XML data for use with this workbook's =FDS codes. Modifying the worksheet's contents may damage the workbook's =FDS functionality.

Sheet 1 — Universe Reconciliation
A1: STEP 4 — Universe Reconciliation | FactSet vs External Research
A2: Compare FactSet universe (from Component A) against names surfaced by AlphaSense, Grok/X and Deep Research. Claude makes ADD / EXCLUDE / CONFIRM recommendations. Analyst approves before Tab 5 scoring.
A4: TICKER | B4: COMPANY NAME | C4: RBICS L5 | D4: FACTSET | E4: ALPHASENSE | F4: GROK/X | G4: DEEP RESEARCH | H4: RECOMMENDATION | I4: RATIONALE / NOTES
A5: Paste FactSet Component A tickers here. Mark each external source with ✓ if name appears. Recommendation: CONFIRM (in FactSet + external) | ADD (external only, passes criteria) | EXCLUDE (FactSet only, Claude recommends remove) | REVIEW (conflicting signals).

Sheet 2 — IC Universe Table
A1: Full RBICS-screened universe — all names passing L5 filter and liquidity floor. Not pre-filtered. Composite Score (col BF) = Claude weighted score. Sort by Score descending before IC presentation.
A2: RANK / ID | C2: IDENTIFICATION | F2: LIQUIDITY | I2: FUNDAMENTAL QUALITY | V2: VALUATION | AB2: MOMENTUM | AH2: SCORING — PERCENTILE RANKS (0–100) | BF2: FINAL SCORE
A3: RANK | B3: TICKER | C3: COMPANY NAME | D3: RBICS L5 NAME | E3: COUNTRY | F3: MKT CAP (USD mm) | G3: ADV 30D (USD mm) | H3: FLOAT (%) | I3: REVENUE ANNUAL | J3: EPS ANNUAL | K3: SALES CAGR NEXT 2Y | L3: EPS CAGR NEXT 2Y | M3: GROSS MARGIN LTM | N3: EBITDA MARGIN LTM | O3: NET PROFIT MARGIN LTM | P3: NET DEBT/EBITDA NTM | Q3: FCF YIELD NTM | R3: DIVIDEND YIELD NTM | S3: ROE NTM | T3: ROIC NTM | U3: RULE OF 40 | V3: P/E NTM | W3: P/S NTM | X3: EV/SALES NTM | Y3: EV/EBITDA NTM | Z3: P/E NTM CHANGE 52W | AA3: EV/EBITDA NTM CHANGE 52W | AB3: PRICE VS 52W HIGH | AC3: TGT PRICE UPSIDE | AD3: PRICE VS 50 DAY MA | AE3: PRICE VS 100 DAY MA | AF3: PRICE VS 200 DAY MA | AG3: ANALYST RATING | AH3: REVENUE SCORE | AI3: EPS SCORE | AJ3: SALES GR SCORE | AK3: EPS GR SCORE | AL3: GROSS MG SCORE | AM3: EBITDA MG SCORE | AN3: NET MG SCORE | AO3: ND/EBITDA SCORE | AP3: FCF YLD SCORE | AQ3: DIV YLD SCORE | AR3: ROE SCORE | AS3: ROIC SCORE | AT3: RULE 40 SCORE | AU3: P/E SCORE | AV3: P/S SCORE | AW3: EV/SALES SCORE | AX3: EV/EBITDA SCORE | AY3: P/E NTM CHANGE 52W2 | AZ3: EV/EBITDA NTM CHANGE 52W3 | BA3: 52W HIGH SCORE | BB3: TGT UPSD SCORE | BC3: VS 50D MA SCORE | BD3: VS 100D MA SCORE | BE3: VS 200D MA SCORE | BF3: CLAUDE SCORE | BG3: CAPE IMC SCORE
A4: =IFERROR(RANK(BG4,BG$4:BG$91),"") -> 1 | B4: HUBS-US | C4: HubSpot, Inc. | D4: {=IFERROR(_xll.FDS($B4,"FR_RBICS_NAME_CURR(""IND"")"), "")} -> Customer Relationship Management Software | E4: {=PROPER(IFERROR(_xll.FDS($B4,"P_DCOUNTRY"), ""))} -> United States | F4: {=IFERROR(_xll.FDS($B4,"FCS_EV_DAILY(MV,NOW,,,USD,M)"), "")} -> 12609.603 | G4: {=IFERROR(_xll.FDS($B4,"AVG(P_VOLUME_FRQ(-1AM,NOW,D,,6))*P_PRICE_AVG(-1AM,NOW,,USD)"), "")} -> 578.23509 | H4: {=IFERROR(_xll.FDS($B4,"OS_SEC_FLT_PCT(0D,,MTD,SEC)")/100, "")} -> 0.962729 | I4: {=IFERROR(_xll.FDS($B4,"FE_ACTUAL(ACTUAL,SALES,ANN_ROLL,0,,,,'CURRENCY=USD')"), "")} -> 3131.266 | J4: {=IFERROR(_xll.FDS($B4,"FE_ACTUAL(ACTUAL,EPS,ANN_ROLL,0,,,,'CURRENCY=USD')"), "")} -> 9.7 | K4: {=IFERROR(_xll.FDS($B4,"POW(FE_ESTIMATE(SALES,MEAN,STMA,,NOW,,,'CURRENCY=USD')/FE_ESTIMATE(SALES,MEAN,LTMA,,NOW,,,'CURRENCY=USD'),0.5)-1"), "")} -> 0.16894538 | L4: {=IFERROR(_xll.FDS($B4,"POW(FE_ESTIMATE(EPS,MEAN,STMA,,NOW,,,'CURRENCY=USD')/FE_ESTIMATE(EPS,MEAN,LTMA,,NOW,,,'CURRENCY=USD'),0.5)-1"), "")} -> 0.2476427 | M4: {=IFERROR(_xll.FDS($B4,"FF_GROSS_MGN(LTM_R,0)"), "")} -> 83.758949 | N4: {=IFERROR(_xll.FDS($B4,"FF_EBITDA_OPER_MGN(LTM_R,0)"), "")} -> 5.6062922 | O4: {=IFERROR(_xll.FDS($B4,"FF_NET_MGN(LTM_R,0)"), "")} -> 1.4663952 | P4: {=IFERROR(_xll.FDS($B4,"FE_VALUATION(NETDEBT_EBITDA,MEAN,NTMA,,NOW,,,'')"), "")} -> -2.2464297 | Q4: {=IFERROR(_xll.FDS($B4,"FE_VALUATION(MCAP_FCF,MEAN,NTMA,,NOW,,,'')"), "")} -> 6.2337174 | R4: {=IFERROR(_xll.FDS($B4,"FE_VALUATION(DIV_YLD,MEAN,NTMA,,NOW,,,'')"), "")} -> 0 | S4: {=IFERROR(_xll.FDS($B4,"FE_VALUATION(ROE,MEAN,NTMA,,0,,,'')" ), "")} -> 25.60649 | T4: {=IFERROR(_xll.FDS($B4,"FE_VALUATION(ROIC,MEAN,NTMA,,0,,,'')" ), "")} -> 23.986855 | U4: {=IFERROR(((_xll.FDS($B4,"FE_ACTUAL(ACTUAL,SALES,ANN_ROLL,0,,,,'CURRENCY=USD')")/_xll.FDS($B4,"FE_ACTUAL(ACTUAL,SALES,ANN_ROLL,-1,,,,'CURRENCY=USD')")-1)*100)+(_xll.FDS($B4,"FE_VALUATION(EBITDA_MARGIN,MEAN,ANN_ROLL,0,NOW,,,'')") ), "")} -> 41.915656 | V4: {=IFERROR(_xll.FDS($B4,"FE_VALUATION(PE,MEAN,NTMA,,0,,,'')" ), "")} -> 18.106287 | W4: {=IFERROR(_xll.FDS($B4,"FE_VALUATION(P_SALESPS,MEAN,NTMA,,0,,,'')" ), "")} -> 3.238714 | X4: {=IFERROR(_xll.FDS($B4,"FE_VALUATION(FFEV_SALES,MEAN,NTMA,,0,,,'')" ), "")} -> 2.8859944 | Y4: {=IFERROR(_xll.FDS($B4,"FE_VALUATION(FFEV_EBITDA,MEAN,NTMA,,0,,,'')" ), "")} -> 11.89469 | Z4: {=IFERROR(_xll.FDS($B4,"PERCENT_CHANGE(FE_VALUATION(PE,MEAN,NTMA,,0,,,''),MAX(FE_VALUATION(PE,MEAN,NTMA,,-1AY,0,,'')))")/100,"")} -> -0.76062538 | AA4: {=IFERROR(_xll.FDS($B4,"PERCENT_CHANGE(FE_VALUATION(FFEV_EBITDA,MEAN,NTMA,,0,,,''),MAX(FE_VALUATION(FFEV_EBITDA,MEAN,NTMA,,-1AY,0,,'')))")/100,"")} -> -0.78299652 | AB4: {=IFERROR(_xll.FDS($B4,"FG_PRICE(0,,,USD)/P_PRICE_HIGH(-1AY,0,USD,,,""PRICE"",""INTRA"")")-1, "")} -> -0.6850543 | AC4: {=IFERROR(_xll.FDS($B4,"RTP_PRICE_TARGET(USD)/FG_PRICE(0,,,USD)")-1, "")} -> 0.51851634 | AD4: {=IFERROR(_xll.FDS($B4,"FG_PRICE(0,,,USD)/FG_PRICE_MAVG(0,,,USD,50)")-1, "")} -> -0.27519839 | AE4: {=IFERROR(_xll.FDS($B4,"FG_PRICE(0,,,USD)/FG_PRICE_MAVG(0,,,USD,100)")-1, "")} -> -0.37289944 | AF4: {=IFERROR(_xll.FDS($B4,"FG_PRICE(0,,,USD)/FG_PRICE_MAVG(0,,,USD,200)")-1, "")} -> -0.48767564 | AG4: {=IFERROR(_xll.FDS($B4,"FE_RATING(MEAN,TEXTONLY,0,NOW,,,'')"), "")} -> Buy | AH4: =IFERROR(IF('3 — Weights'!$E$2=1,PERCENTRANK(I$4:I$91,I4),1-PERCENTRANK(I$4:I$91,I4))*100,"") -> 67.8 | AI4: =IFERROR(IF('3 — Weights'!$E$3=1,PERCENTRANK(J$4:J$91,J4),1-PERCENTRANK(J$4:J$91,J4))*100,"") -> 88.5 | AJ4: =IFERROR(IF('3 — Weights'!$E$4=1,PERCENTRANK(K$4:K$91,K4),1-PERCENTRANK(K$4:K$91,K4))*100,"") -> 68.9 | AK4: =IFERROR(IF('3 — Weights'!$E$5=1,PERCENTRANK(L$4:L$91,L4),1-PERCENTRANK(L$4:L$91,L4))*100,"") -> 75 | AL4: =IFERROR(IF('3 — Weights'!$E$6=1,PERCENTRANK(M$4:M$91,M4),1-PERCENTRANK(M$4:M$91,M4))*100,"") -> 92.6 | AM4: =IFERROR(IF('3 — Weights'!$E$7=1,PERCENTRANK(N$4:N$91,N4),1-PERCENTRANK(N$4:N$91,N4))*100,"") -> 25.9 | AN4: =IFERROR(IF('3 — Weights'!$E$8=1,PERCENTRANK(O$4:O$91,O4),1-PERCENTRANK(O$4:O$91,O4))*100,"") -> 31.3 | AO4: =IFERROR(IF('3 — Weights'!$E$9=1,PERCENTRANK(P$4:P$91,P4),1-PERCENTRANK(P$4:P$91,P4))*100,"") -> 71.1 | AP4: =IFERROR(IF('3 — Weights'!$E$10=1,PERCENTRANK(Q$4:Q$91,Q4),1-PERCENTRANK(Q$4:Q$91,Q4))*100,"") -> 63 | AQ4: =IFERROR(IF('3 — Weights'!$E$11=1,PERCENTRANK(R$4:R$91,R4),1-PERCENTRANK(R$4:R$91,R4))*100,"") -> 0 | AR4: =IFERROR(IF('3 — Weights'!$E$12=1,PERCENTRANK(S$4:S$91,S4),1-PERCENTRANK(S$4:S$91,S4))*100,"") -> 64.1 | AS4: =IFERROR(IF('3 — Weights'!$E$13=1,PERCENTRANK(T$4:T$91,T4),1-PERCENTRANK(T$4:T$91,T4))*100,"") -> 73.6 | AT4: =IFERROR(IF('3 — Weights'!$E$14=1,PERCENTRANK(U$4:U$91,U4),1-PERCENTRANK(U$4:U$91,U4))*100,"") -> 42.6 | AU4: =IFERROR(IF('3 — Weights'!$E$15=1,PERCENTRANK(V$4:V$91,V4),1-PERCENTRANK(V$4:V$91,V4))*100,"") -> 65.6 | AV4: =IFERROR(IF('3 — Weights'!$E$16=1,PERCENTRANK(W$4:W$91,W4),1-PERCENTRANK(W$4:W$91,W4))*100,"") -> 70.2 | AW4: =IFERROR(IF('3 — Weights'!$E$17=1,PERCENTRANK(X$4:X$91,X4),1-PERCENTRANK(X$4:X$91,X4))*100,"") -> 81.7 | AX4: =IFERROR(IF('3 — Weights'!$E$18=1,PERCENTRANK(Y$4:Y$91,Y4),1-PERCENTRANK(Y$4:Y$91,Y4))*100,"") -> 68.7 | AY4: =IFERROR(IF('3 — Weights'!$E$18=1,PERCENTRANK(Z$4:Z$91,Z4),1-PERCENTRANK(Z$4:Z$91,Z4))*100,"") -> 95.5 | AZ4: =IFERROR(IF('3 — Weights'!$E$18=1,PERCENTRANK(AA$4:AA$91,AA4),1-PERCENTRANK(AA$4:AA$91,AA4))*100,"") -> 98.9 | BA4: =IFERROR(IF('3 — Weights'!$E$21=1,PERCENTRANK(AB$4:AB$91,AB4),1-PERCENTRANK(AB$4:AB$91,AB4))*100,"") -> 2.2 | BB4: =IFERROR(IF('3 — Weights'!$E$22=1,PERCENTRANK(AC$4:AC$91,AC4),1-PERCENTRANK(AC$4:AC$91,AC4))*100,"") -> 49.4 | BC4: =IFERROR(IF('3 — Weights'!$E$23=1,PERCENTRANK(AD$4:AD$91,AD4),1-PERCENTRANK(AD$4:AD$91,AD4))*100,"") -> 86.3 | BD4: =IFERROR(IF('3 — Weights'!$E$24=1,PERCENTRANK(AE$4:AE$91,AE4),1-PERCENTRANK(AE$4:AE$91,AE4))*100,"") -> 92 | BE4: =IFERROR(IF('3 — Weights'!$E$25=1,PERCENTRANK(AF$4:AF$91,AF4),1-PERCENTRANK(AF$4:AF$91,AF4))*100,"") -> 95.5 | BF4: {=IFERROR(SUMPRODUCT(TRANSPOSE(AH4:BE4), [1]!Table2[Weight Claude]),"")} -> 67.865 | BG4: {=IFERROR(SUMPRODUCT(TRANSPOSE(AH4:BE4), [1]!Table2[Weight Cape IMC]),"")} -> 67.865
A5: =IFERROR(RANK(BG5,BG$4:BG$91),"") -> 2 | B5: NTNX-US | C5: Nutanix, Inc. | D5: {=IFERROR(_xll.FDS($B5,"FR_RBICS_NAME_CURR(""IND"")"), "")} -> Data Storage Infrastructure Software | E5: {=PROPER(IFERROR(_xll.FDS($B5,"P_DCOUNTRY"), ""))} -> United States | F5: {=IFERROR(_xll.FDS($B5,"FCS_EV_DAILY(MV,NOW,,,USD,M)"), "")} -> 10743.046 | G5: {=IFERROR(_xll.FDS($B5,"AVG(P_VOLUME_FRQ(-1AM,NOW,D,,6))*P_PRICE_AVG(-1AM,NOW,,USD)"), "")} -> 167.96063 | H5: {=IFERROR(_xll.FDS($B5,"OS_SEC_FLT_PCT(0D,,MTD,SEC)")/100, "")} -> 0.975413 | I5: {=IFERROR(_xll.FDS($B5,"FE_ACTUAL(ACTUAL,SALES,ANN_ROLL,0,,,,'CURRENCY=USD')"), "")} -> 2537.927 | J5: {=IFERROR(_xll.FDS($B5,"FE_ACTUAL(ACTUAL,EPS,ANN_ROLL,0,,,,'CURRENCY=USD')"), "")} -> 1.78 | K5: {=IFERROR(_xll.FDS($B5,"POW(FE_ESTIMATE(SALES,MEAN,STMA,,NOW,,,'CURRENCY=USD')/FE_ESTIMATE(SALES,MEAN,LTMA,,NOW,,,'CURRENCY=USD'),0.5)-1"), "")} -> 0.12762747 | L5: {=IFERROR(_xll.FDS($B5,"POW(FE_ESTIMATE(EPS,MEAN,STMA,,NOW,,,'CURRENCY=USD')/FE_ESTIMATE(EPS,MEAN,LTMA,,NOW,,,'CURRENCY=USD'),0.5)-1"), "")} -> 0.14773324 | M5: {=IFERROR(_xll.FDS($B5,"FF_GROSS_MGN(LTM_R,0)"), "")} -> 87.013223 | N5: {=IFERROR(_xll.FDS($B5,"FF_EBITDA_OPER_MGN(LTM_R,0)"), "")} -> 10.771803 | O5: {=IFERROR(_xll.FDS($B5,"FF_NET_MGN(LTM_R,0)"), "")} -> 8.4252928 | P5: {=IFERROR(_xll.FDS($B5,"FE_VALUATION(NETDEBT_EBITDA,MEAN,NTMA,,NOW,,,'')"), "")} -> -2.2384424 | Q5: {=IFERROR(_xll.FDS($B5,"FE_VALUATION(MCAP_FCF,MEAN,NTMA,,NOW,,,'')"), "")} -> 8.521549 | R5: {=IFERROR(_xll.FDS($B5,"FE_VALUATION(DIV_YLD,MEAN,NTMA,,NOW,,,'')"), "")} -> 0 | S5: {=IFERROR(_xll.FDS($B5,"FE_VALUATION(ROE,MEAN,NTMA,,0,,,'')" ), "")} -> 1583.1248 | T5: {=IFERROR(_xll.FDS($B5,"FE_VALUATION(ROIC,MEAN,NTMA,,0,,,'')" ), "")} -> 44.851734 | U5: {=IFERROR(((_xll.FDS($B5,"FE_ACTUAL(ACTUAL,SALES,ANN_ROLL,0,,,,'CURRENCY=USD')")/_xll.FDS($B5,"FE_ACTUAL(ACTUAL,SALES,ANN_ROLL,-1,,,,'CURRENCY=USD')")-1)*100)+(_xll.FDS($B5,"FE_VALUATION(EBITDA_MARGIN,MEAN,ANN_ROLL,0,NOW,,,'')") ), "")} -> 42.097692 | V5: {=IFERROR(_xll.FDS($B5,"FE_VALUATION(PE,MEAN,NTMA,,0,,,'')" ), "")} -> 19.05695 | W5: {=IFERROR(_xll.FDS($B5,"FE_VALUATION(P_SALESPS,MEAN,NTMA,,0,,,'')" ), "")} -> 3.3473253 | X5: {=IFERROR(_xll.FDS($B5,"FE_VALUATION(FFEV_SALES,MEAN,NTMA,,0,,,'')" ), "")} -> 3.4821198 | Y5: {=IFERROR(_xll.FDS($B5,"FE_VALUATION(FFEV_EBITDA,MEAN,NTMA,,0,,,'')" ), "")} -> 13.97298 | Z5: {=IFERROR(_xll.FDS($B5,"PERCENT_CHANGE(FE_VALUATION(PE,MEAN,NTMA,,0,,,''),MAX(FE_VALUATION(PE,MEAN,NTMA,,-1AY,0,,'')))")/100,"")} -> -0.58102081 | AA5: {=IFERROR(_xll.FDS($B5,"PERCENT_CHANGE(FE_VALUATION(FFEV_EBITDA,MEAN,NTMA,,0,,,''),MAX(FE_VALUATION(FFEV_EBITDA,MEAN,NTMA,,-1AY,0,,'')))")/100,"")} -> -0.63910111 | AB5: {=IFERROR(_xll.FDS($B5,"FG_PRICE(0,,,USD)/P_PRICE_HIGH(-1AY,0,USD,,,""PRICE"",""INTRA"")")-1, "")} -> -0.54582534 | AC5: {=IFERROR(_xll.FDS($B5,"RTP_PRICE_TARGET(USD)/FG_PRICE(0,,,USD)")-1, "")} -> 0.60104023 | AD5: {=IFERROR(_xll.FDS($B5,"FG_PRICE(0,,,USD)/FG_PRICE_MAVG(0,,,USD,50)")-1, "")} -> -0.17404773 | AE5: {=IFERROR(_xll.FDS($B5,"FG_PRICE(0,,,USD)/FG_PRICE_MAVG(0,,,USD,100)")-1, "")} -> -0.31066126 | AF5: {=IFERROR(_xll.FDS($B5,"FG_PRICE(0,,,USD)/FG_PRICE_MAVG(0,,,USD,200)")-1, "")} -> -0.41555088 | AG5: {=IFERROR(_xll.FDS($B5,"FE_RATING(MEAN,TEXTONLY,0,NOW,,,'')"), "")} -> Overweight | AH5: =IFERROR(IF('3 — Weights'!$E$2=1,PERCENTRANK(I$4:I$91,I5),1-PERCENTRANK(I$4:I$91,I5))*100,"") -> 60.9 | AI5: =IFERROR(IF('3 — Weights'!$E$3=1,PERCENTRANK(J$4:J$91,J5),1-PERCENTRANK(J$4:J$91,J5))*100,"") -> 42.5 | AJ5: =IFERROR(IF('3 — Weights'!$E$4=1,PERCENTRANK(K$4:K$91,K5),1-PERCENTRANK(K$4:K$91,K5))*100,"") -> 49.4 | AK5: =IFERROR(IF('3 — Weights'!$E$5=1,PERCENTRANK(L$4:L$91,L5),1-PERCENTRANK(L$4:L$91,L5))*100,"") -> 42.8 | AL5: =IFERROR(IF('3 — Weights'!$E$6=1,PERCENTRANK(M$4:M$91,M5),1-PERCENTRANK(M$4:M$91,M5))*100,"") -> 97.5 | AM5: =IFERROR(IF('3 — Weights'!$E$7=1,PERCENTRANK(N$4:N$91,N5),1-PERCENTRANK(N$4:N$91,N5))*100,"") -> 35 | AN5: =IFERROR(IF('3 — Weights'!$E$8=1,PERCENTRANK(O$4:O$91,O5),1-PERCENTRANK(O$4:O$91,O5))*100,"") -> 44.5 | AO5: =IFERROR(IF('3 — Weights'!$E$9=1,PERCENTRANK(P$4:P$91,P5),1-PERCENTRANK(P$4:P$91,P5))*100,"") -> 69.9 | AP5: =IFERROR(IF('3 — Weights'!$E$10=1,PERCENTRANK(Q$4:Q$91,Q5),1-PERCENTRANK(Q$4:Q$91,Q5))*100,"") -> 83.3 | AQ5: =IFERROR(IF('3 — Weights'!$E$11=1,PERCENTRANK(R$4:R$91,R5),1-PERCENTRANK(R$4:R$91,R5))*100,"") -> 0 | AR5: =IFERROR(IF('3 — Weights'!$E$12=1,PERCENTRANK(S$4:S$91,S5),1-PERCENTRANK(S$4:S$91,S5))*100,"") -> 100 | AS5: =IFERROR(IF('3 — Weights'!$E$13=1,PERCENTRANK(T$4:T$91,T5),1-PERCENTRANK(T$4:T$91,T5))*100,"") -> 95.8 | AT5: =IFERROR(IF('3 — Weights'!$E$14=1,PERCENTRANK(U$4:U$91,U5),1-PERCENTRANK(U$4:U$91,U5))*100,"") -> 43.9 | AU5: =IFERROR(IF('3 — Weights'!$E$15=1,PERCENTRANK(V$4:V$91,V5),1-PERCENTRANK(V$4:V$91,V5))*100,"") -> 57.5 | AV5: =IFERROR(IF('3 — Weights'!$E$16=1,PERCENTRANK(W$4:W$91,W5),1-PERCENTRANK(W$4:W$91,W5))*100,"") -> 67.9 | AW5: =IFERROR(IF('3 — Weights'!$E$17=1,PERCENTRANK(X$4:X$91,X5),1-PERCENTRANK(X$4:X$91,X5))*100,"") -> 65.6 | AX5: =IFERROR(IF('3 — Weights'!$E$18=1,PERCENTRANK(Y$4:Y$91,Y5),1-PERCENTRANK(Y$4:Y$91,Y5))*100,"") -> 57 | AY5: =IFERROR(IF('3 — Weights'!$E$18=1,PERCENTRANK(Z$4:Z$91,Z5),1-PERCENTRANK(Z$4:Z$91,Z5))*100,"") -> 63.3 | AZ5: =IFERROR(IF('3 — Weights'!$E$18=1,PERCENTRANK(AA$4:AA$91,AA5),1-PERCENTRANK(AA$4:AA$91,AA5))*100,"") -> 83.8 | BA5: =IFERROR(IF('3 — Weights'!$E$21=1,PERCENTRANK(AB$4:AB$91,AB5),1-PERCENTRANK(AB$4:AB$91,AB5))*100,"") -> 16 | BB5: =IFERROR(IF('3 — Weights'!$E$22=1,PERCENTRANK(AC$4:AC$91,AC5),1-PERCENTRANK(AC$4:AC$91,AC5))*100,"") -> 62 | BC5: =IFERROR(IF('3 — Weights'!$E$23=1,PERCENTRANK(AD$4:AD$91,AD5),1-PERCENTRANK(AD$4:AD$91,AD5))*100,"") -> 43.7 | BD5: =IFERROR(IF('3 — Weights'!$E$24=1,PERCENTRANK(AE$4:AE$91,AE5),1-PERCENTRANK(AE$4:AE$91,AE5))*100,"") -> 73.6 | BE5: =IFERROR(IF('3 — Weights'!$E$25=1,PERCENTRANK(AF$4:AF$91,AF5),1-PERCENTRANK(AF$4:AF$91,AF5))*100,"") -> 87.4 | BF5: {=IFERROR(SUMPRODUCT(TRANSPOSE(AH5:BE5), [1]!Table2[Weight Claude]),"")} -> 66.91 | BG5: {=IFERROR(SUMPRODUCT(TRANSPOSE(AH5:BE5), [1]!Table2[Weight Cape IMC]),"")} -> 66.91
A6: =IFERROR(RANK(BG6,BG$4:BG$91),"") -> 4 | B6: APP-US | C6: AppLovin Corp. Class A | D6: {=IFERROR(_xll.FDS($B6,"FR_RBICS_NAME_CURR(""IND"")"), "")} -> Customer Relationship Management Software | E6: {=PROPER(IFERROR(_xll.FDS($B6,"P_DCOUNTRY"), ""))} -> United States | F6: {=IFERROR(_xll.FDS($B6,"FCS_EV_DAILY(MV,NOW,,,USD,M)"), "")} -> 133672.51 | G6: {=IFERROR(_xll.FDS($B6,"AVG(P_VOLUME_FRQ(-1AM,NOW,D,,6))*P_PRICE_AVG(-1AM,NOW,,USD)"), "")} -> 3372.0398 | H6: {=IFERROR(_xll.FDS($B6,"OS_SEC_FLT_PCT(0D,,MTD,SEC)")/100, "")} -> 0.726322 | I6: {=IFERROR(_xll.FDS($B6,"FE_ACTUAL(ACTUAL,SALES,ANN_ROLL,0,,,,'CURRENCY=USD')"), "")} -> 5480.717 | J6: {=IFERROR(_xll.FDS($B6,"FE_ACTUAL(ACTUAL,EPS,ANN_ROLL,0,,,,'CURRENCY=USD')"), "")} -> 9.75 | K6: {=IFERROR(_xll.FDS($B6,"POW(FE_ESTIMATE(SALES,MEAN,STMA,,NOW,,,'CURRENCY=USD')/FE_ESTIMATE(SALES,MEAN,LTMA,,NOW,,,'CURRENCY=USD'),0.5)-1"), "")} -> 0.34842794 | L6: {=IFERROR(_xll.FDS($B6,"POW(FE_ESTIMATE(EPS,MEAN,STMA,,NOW,,,'CURRENCY=USD')/FE_ESTIMATE(EPS,MEAN,LTMA,,NOW,,,'CURRENCY=USD'),0.5)-1"), "")} -> 0.42091098 | M6: {=IFERROR(_xll.FDS($B6,"FF_GROSS_MGN(LTM_R,0)"), "")} -> 85.470904 | N6: {=IFERROR(_xll.FDS($B6,"FF_EBITDA_OPER_MGN(LTM_R,0)"), "")} -> 75.735838 | O6: {=IFERROR(_xll.FDS($B6,"FF_NET_MGN(LTM_R,0)"), "")} -> 56.592276 | P6: {=IFERROR(_xll.FDS($B6,"FE_VALUATION(NETDEBT_EBITDA,MEAN,NTMA,,NOW,,,'')"), "")} -> -0.42884582 | Q6: {=IFERROR(_xll.FDS($B6,"FE_VALUATION(MCAP_FCF,MEAN,NTMA,,NOW,,,'')"), "")} -> 4.0581355 | R6: {=IFERROR(_xll.FDS($B6,"FE_VALUATION(DIV_YLD,MEAN,NTMA,,NOW,,,'')"), "")} -> 0 | S6: {=IFERROR(_xll.FDS($B6,"FE_VALUATION(ROE,MEAN,NTMA,,0,,,'')" ), "")} -> 103.1667 | T6: {=IFERROR(_xll.FDS($B6,"FE_VALUATION(ROIC,MEAN,NTMA,,0,,,'')" ), "")} -> 54.05012 | U6: {=IFERROR(((_xll.FDS($B6,"FE_ACTUAL(ACTUAL,SALES,ANN_ROLL,0,,,,'CURRENCY=USD')")/_xll.FDS($B6,"FE_ACTUAL(ACTUAL,SALES,ANN_ROLL,-1,,,,'CURRENCY=USD')")-1)*100)+(_xll.FDS($B6,"FE_VALUATION(EBITDA_MARGIN,MEAN,ANN_ROLL,0,NOW,,,'')") ), "")} -> 98.71525 | V6: {=IFERROR(_xll.FDS($B6,"FE_VALUATION(PE,MEAN,NTMA,,0,,,'')" ), "")} -> 24.144264 | W6: {=IFERROR(_xll.FDS($B6,"FE_VALUATION(P_SALESPS,MEAN,NTMA,,0,,,'')" ), "")} -> 16.01234 | X6: {=IFERROR(_xll.FDS($B6,"FE_VALUATION(FFEV_SALES,MEAN,NTMA,,0,,,'')" ), "")} -> 16.355515 | Y6: {=IFERROR(_xll.FDS($B6,"FE_VALUATION(FFEV_EBITDA,MEAN,NTMA,,0,,,'')" ), "")} -> 19.3847 | Z6: {=IFERROR(_xll.FDS($B6,"PERCENT_CHANGE(FE_VALUATION(PE,MEAN,NTMA,,0,,,''),MAX(FE_VALUATION(PE,MEAN,NTMA,,-1AY,0,,'')))")/100,"")} -> -0.58231354 | AA6: {=IFERROR(_xll.FDS($B6,"PERCENT_CHANGE(FE_VALUATION(FFEV_EBITDA,MEAN,NTMA,,0,,,''),MAX(FE_VALUATION(FFEV_EBITDA,MEAN,NTMA,,-1AY,0,,'')))")/100,"")} -> -0.55731331 | AB6: {=IFERROR(_xll.FDS($B6,"FG_PRICE(0,,,USD)/P_PRICE_HIGH(-1AY,0,USD,,,""PRICE"",""INTRA"")")-1, "")} -> -0.47261973 | AC6: {=IFERROR(_xll.FDS($B6,"RTP_PRICE_TARGET(USD)/FG_PRICE(0,,,USD)")-1, "")} -> 0.70164285 | AD6: {=IFERROR(_xll.FDS($B6,"FG_PRICE(0,,,USD)/FG_PRICE_MAVG(0,,,USD,50)")-1, "")} -> -0.3009329 | AE6: {=IFERROR(_xll.FDS($B6,"FG_PRICE(0,,,USD)/FG_PRICE_MAVG(0,,,USD,100)")-1, "")} -> -0.32975212 | AF6: {=IFERROR(_xll.FDS($B6,"FG_PRICE(0,,,USD)/FG_PRICE_MAVG(0,,,USD,200)")-1, "")} -> -0.22455901 | AG6: {=IFERROR(_xll.FDS($B6,"FE_RATING(MEAN,TEXTONLY,0,NOW,,,'')"), "")} -> Buy | AH6: =IFERROR(IF('3 — Weights'!$E$2=1,PERCENTRANK(I$4:I$91,I6),1-PERCENTRANK(I$4:I$91,I6))*100,"") -> 79.3 | AI6: =IFERROR(IF('3 — Weights'!$E$3=1,PERCENTRANK(J$4:J$91,J6),1-PERCENTRANK(J$4:J$91,J6))*100,"") -> 89.6 | AJ6: =IFERROR(IF('3 — Weights'!$E$4=1,PERCENTRANK(K$4:K$91,K6),1-PERCENTRANK(K$4:K$91,K6))*100,"") -> 97.7 | AK6: =IFERROR(IF('3 — Weights'!$E$5=1,PERCENTRANK(L$4:L$91,L6),1-PERCENTRANK(L$4:L$91,L6))*100,"") -> 91.6 | AL6: =IFERROR(IF('3 — Weights'!$E$6=1,PERCENTRANK(M$4:M$91,M6),1-PERCENTRANK(M$4:M$91,M6))*100,"") -> 95.1 | AM6: =IFERROR(IF('3 — Weights'!$E$7=1,PERCENTRANK(N$4:N$91,N6),1-PERCENTRANK(N$4:N$91,N6))*100,"") -> 100 | AN6: =IFERROR(IF('3 — Weights'!$E$8=1,PERCENTRANK(O$4:O$91,O6),1-PERCENTRANK(O$4:O$91,O6))*100,"") -> 98.7 | AO6: =IFERROR(IF('3 — Weights'!$E$9=1,PERCENTRANK(P$4:P$91,P6),1-PERCENTRANK(P$4:P$91,P6))*100,"") -> 35 | AP6: =IFERROR(IF('3 — Weights'!$E$10=1,PERCENTRANK(Q$4:Q$91,Q6),1-PERCENTRANK(Q$4:Q$91,Q6))*100,"") -> 35.7 | AQ6: =IFERROR(IF('3 — Weights'!$E$11=1,PERCENTRANK(R$4:R$91,R6),1-PERCENTRANK(R$4:R$91,R6))*100,"") -> 0 | AR6: =IFERROR(IF('3 — Weights'!$E$12=1,PERCENTRANK(S$4:S$91,S6),1-PERCENTRANK(S$4:S$91,S6))*100,"") -> 97.5 | AS6: =IFERROR(IF('3 — Weights'!$E$13=1,PERCENTRANK(T$4:T$91,T6),1-PERCENTRANK(T$4:T$91,T6))*100,"") -> 98.6 | AT6: =IFERROR(IF('3 — Weights'!$E$14=1,PERCENTRANK(U$4:U$91,U6),1-PERCENTRANK(U$4:U$91,U6))*100,"") -> 97.5 | AU6: =IFERROR(IF('3 — Weights'!$E$15=1,PERCENTRANK(V$4:V$91,V6),1-PERCENTRANK(V$4:V$91,V6))*100,"") -> 42.6 | AV6: =IFERROR(IF('3 — Weights'!$E$16=1,PERCENTRANK(W$4:W$91,W6),1-PERCENTRANK(W$4:W$91,W6))*100,"") -> 4.6 | AW6: =IFERROR(IF('3 — Weights'!$E$17=1,PERCENTRANK(X$4:X$91,X6),1-PERCENTRANK(X$4:X$91,X6))*100,"") -> 4.6 | AX6: =IFERROR(IF('3 — Weights'!$E$18=1,PERCENTRANK(Y$4:Y$91,Y6),1-PERCENTRANK(Y$4:Y$91,Y6))*100,"") -> 33.8 | AY6: =IFERROR(IF('3 — Weights'!$E$18=1,PERCENTRANK(Z$4:Z$91,Z6),1-PERCENTRANK(Z$4:Z$91,Z6))*100,"") -> 64.4 | AZ6: =IFERROR(IF('3 — Weights'!$E$18=1,PERCENTRANK(AA$4:AA$91,AA6),1-PERCENTRANK(AA$4:AA$91,AA6))*100,"") -> 59.4 | BA6: =IFERROR(IF('3 — Weights'!$E$21=1,PERCENTRANK(AB$4:AB$91,AB6),1-PERCENTRANK(AB$4:AB$91,AB6))*100,"") -> 41.3 | BB6: =IFERROR(IF('3 — Weights'!$E$22=1,PERCENTRANK(AC$4:AC$91,AC6),1-PERCENTRANK(AC$4:AC$91,AC6))*100,"") -> 75.8 | BC6: =IFERROR(IF('3 — Weights'!$E$23=1,PERCENTRANK(AD$4:AD$91,AD6),1-PERCENTRANK(AD$4:AD$91,AD6))*100,"") -> 89.7 | BD6: =IFERROR(IF('3 — Weights'!$E$24=1,PERCENTRANK(AE$4:AE$91,AE6),1-PERCENTRANK(AE$4:AE$91,AE6))*100,"") -> 81.7 | BE6: =IFERROR(IF('3 — Weights'!$E$25=1,PERCENTRANK(AF$4:AF$91,AF6),1-PERCENTRANK(AF$4:AF$91,AF6))*100,"") -> 31.1 | BF6: {=IFERROR(SUMPRODUCT(TRANSPOSE(AH6:BE6), [1]!Table2[Weight Claude]),"")} -> 66.26 | BG6: {=IFERROR(SUMPRODUCT(TRANSPOSE(AH6:BE6), [1]!Table2[Weight Cape IMC]),"")} -> 66.26
A7: =IFERROR(RANK(BG7,BG$4:BG$91),"") -> 3 | B7: QLYS-US | C7: Qualys, Inc. | D7: {=IFERROR(_xll.FDS($B7,"FR_RBICS_NAME_CURR(""IND"")"), "")} -> Network Infrastructure Software | E7: {=PROPER(IFERROR(_xll.FDS($B7,"P_DCOUNTRY"), ""))} -> United States | F7: {=IFERROR(_xll.FDS($B7,"FCS_EV_DAILY(MV,NOW,,,USD,M)"), "")} -> 3197.4215 | G7: {=IFERROR(_xll.FDS($B7,"AVG(P_VOLUME_FRQ(-1AM,NOW,D,,6))*P_PRICE_AVG(-1AM,NOW,,USD)"), "")} -> 90.699946 | H7: {=IFERROR(_xll.FDS($B7,"OS_SEC_FLT_PCT(0D,,MTD,SEC)")/100, "")} -> 0.986738 | I7: {=IFERROR(_xll.FDS($B7,"FE_ACTUAL(ACTUAL,SALES,ANN_ROLL,0,,,,'CURRENCY=USD')"), "")} -> 669.125 | J7: {=IFERROR(_xll.FDS($B7,"FE_ACTUAL(ACTUAL,EPS,ANN_ROLL,0,,,,'CURRENCY=USD')"), "")} -> 7.07 | K7: {=IFERROR(_xll.FDS($B7,"POW(FE_ESTIMATE(SALES,MEAN,STMA,,NOW,,,'CURRENCY=USD')/FE_ESTIMATE(SALES,MEAN,LTMA,,NOW,,,'CURRENCY=USD'),0.5)-1"), "")} -> 0.073531089 | L7: {=IFERROR(_xll.FDS($B7,"POW(FE_ESTIMATE(EPS,MEAN,STMA,,NOW,,,'CURRENCY=USD')/FE_ESTIMATE(EPS,MEAN,LTMA,,NOW,,,'CURRENCY=USD'),0.5)-1"), "")} -> 0.063374111 | M7: {=IFERROR(_xll.FDS($B7,"FF_GROSS_MGN(LTM_R,0)"), "")} -> 82.89279 | N7: {=IFERROR(_xll.FDS($B7,"FF_EBITDA_OPER_MGN(LTM_R,0)"), "")} -> 35.531867 | O7: {=IFERROR(_xll.FDS($B7,"FF_NET_MGN(LTM_R,0)"), "")} -> 29.646638 | P7: {=IFERROR(_xll.FDS($B7,"FE_VALUATION(NETDEBT_EBITDA,MEAN,NTMA,,NOW,,,'')"), "")} -> -2.324673 | Q7: {=IFERROR(_xll.FDS($B7,"FE_VALUATION(MCAP_FCF,MEAN,NTMA,,NOW,,,'')"), "")} -> 9.681528 | R7: {=IFERROR(_xll.FDS($B7,"FE_VALUATION(DIV_YLD,MEAN,NTMA,,NOW,,,'')"), "")} -> 0 | S7: {=IFERROR(_xll.FDS($B7,"FE_VALUATION(ROE,MEAN,NTMA,,0,,,'')" ), "")} -> 36.514206 | T7: {=IFERROR(_xll.FDS($B7,"FE_VALUATION(ROIC,MEAN,NTMA,,0,,,'')" ), "")} -> 35.78148 | U7: {=IFERROR(((_xll.FDS($B7,"FE_ACTUAL(ACTUAL,SALES,ANN_ROLL,0,,,,'CURRENCY=USD')")/_xll.FDS($B7,"FE_ACTUAL(ACTUAL,SALES,ANN_ROLL,-1,,,,'CURRENCY=USD')")-1)*100)+(_xll.FDS($B7,"FE_VALUATION(EBITDA_MARGIN,MEAN,ANN_ROLL,0,NOW,,,'')") ), "")} -> 56.975736 | V7: {=IFERROR(_xll.FDS($B7,"FE_VALUATION(PE,MEAN,NTMA,,0,,,'')" ), "")} -> 11.629527 | W7: {=IFERROR(_xll.FDS($B7,"FE_VALUATION(P_SALESPS,MEAN,NTMA,,0,,,'')" ), "")} -> 4.249773 | X7: {=IFERROR(_xll.FDS($B7,"FE_VALUATION(FFEV_SALES,MEAN,NTMA,,0,,,'')" ), "")} -> 3.802272 | Y7: {=IFERROR(_xll.FDS($B7,"FE_VALUATION(FFEV_EBITDA,MEAN,NTMA,,0,,,'')" ), "")} -> 8.539159 | Z7: {=IFERROR(_xll.FDS($B7,"PERCENT_CHANGE(FE_VALUATION(PE,MEAN,NTMA,,0,,,''),MAX(FE_VALUATION(PE,MEAN,NTMA,,-1AY,0,,'')))")/100,"")} -> -0.50436705 | AA7: {=IFERROR(_xll.FDS($B7,"PERCENT_CHANGE(FE_VALUATION(FFEV_EBITDA,MEAN,NTMA,,0,,,''),MAX(FE_VALUATION(FFEV_EBITDA,MEAN,NTMA,,-1AY,0,,'')))")/100,"")} -> -0.51984789 | AB7: {=IFERROR(_xll.FDS($B7,"FG_PRICE(0,,,USD)/P_PRICE_HIGH(-1AY,0,USD,,,""PRICE"",""INTRA"")")-1, "")} -> -0.44149997 | AC7: {=IFERROR(_xll.FDS($B7,"RTP_PRICE_TARGET(USD)/FG_PRICE(0,,,USD)")-1, "")} -> 0.5906674 | AD7: {=IFERROR(_xll.FDS($B7,"FG_PRICE(0,,,USD)/FG_PRICE_MAVG(0,,,USD,50)")-1, "")} -> -0.31967086 | AE7: {=IFERROR(_xll.FDS($B7,"FG_PRICE(0,,,USD)/FG_PRICE_MAVG(0,,,USD,100)")-1, "")} -> -0.34233797 | AF7: {=IFERROR(_xll.FDS($B7,"FG_PRICE(0,,,USD)/FG_PRICE_MAVG(0,,,USD,200)")-1, "")} -> -0.35358095 | AG7: {=IFERROR(_xll.FDS($B7,"FE_RATING(MEAN,TEXTONLY,0,NOW,,,'')"), "")} -> Hold | AH7: =IFERROR(IF('3 — Weights'!$E$2=1,PERCENTRANK(I$4:I$91,I7),1-PERCENTRANK(I$4:I$91,I7))*100,"") -> 11.4 | AI7: =IFERROR(IF('3 — Weights'!$E$3=1,PERCENTRANK(J$4:J$91,J7),1-PERCENTRANK(J$4:J$91,J7))*100,"") -> 79.3 | AJ7: =IFERROR(IF('3 — Weights'!$E$4=1,PERCENTRANK(K$4:K$91,K7),1-PERCENTRANK(K$4:K$91,K7))*100,"") -> 19.5 | AK7: =IFERROR(IF('3 — Weights'!$E$5=1,PERCENTRANK(L$4:L$91,L7),1-PERCENTRANK(L$4:L$91,L7))*100,"") -> 2.3 | AL7: =IFERROR(IF('3 — Weights'!$E$6=1,PERCENTRANK(M$4:M$91,M7),1-PERCENTRANK(M$4:M$91,M7))*100,"") -> 90.2 | AM7: =IFERROR(IF('3 — Weights'!$E$7=1,PERCENTRANK(N$4:N$91,N7),1-PERCENTRANK(N$4:N$91,N7))*100,"") -> 83.1 | AN7: =IFERROR(IF('3 — Weights'!$E$8=1,PERCENTRANK(O$4:O$91,O7),1-PERCENTRANK(O$4:O$91,O7))*100,"") -> 90.3 | AO7: =IFERROR(IF('3 — Weights'!$E$9=1,PERCENTRANK(P$4:P$91,P7),1-PERCENTRANK(P$4:P$91,P7))*100,"") -> 72.3 | AP7: =IFERROR(IF('3 — Weights'!$E$10=1,PERCENTRANK(Q$4:Q$91,Q7),1-PERCENTRANK(Q$4:Q$91,Q7))*100,"") -> 94 | AQ7: =IFERROR(IF('3 — Weights'!$E$11=1,PERCENTRANK(R$4:R$91,R7),1-PERCENTRANK(R$4:R$91,R7))*100,"") -> 0 | AR7: =IFERROR(IF('3 — Weights'!$E$12=1,PERCENTRANK(S$4:S$91,S7),1-PERCENTRANK(S$4:S$91,S7))*100,"") -> 83.9 | AS7: =IFERROR(IF('3 — Weights'!$E$13=1,PERCENTRANK(T$4:T$91,T7),1-PERCENTRANK(T$4:T$91,T7))*100,"") -> 93 | AT7: =IFERROR(IF('3 — Weights'!$E$14=1,PERCENTRANK(U$4:U$91,U7),1-PERCENTRANK(U$4:U$91,U7))*100,"") -> 78 | AU7: =IFERROR(IF('3 — Weights'!$E$15=1,PERCENTRANK(V$4:V$91,V7),1-PERCENTRANK(V$4:V$91,V7))*100,"") -> 89.7 | AV7: =IFERROR(IF('3 — Weights'!$E$16=1,PERCENTRANK(W$4:W$91,W7),1-PERCENTRANK(W$4:W$91,W7))*100,"") -> 56.4 | AW7: =IFERROR(IF('3 — Weights'!$E$17=1,PERCENTRANK(X$4:X$91,X7),1-PERCENTRANK(X$4:X$91,X7))*100,"") -> 59.8 | AX7: =IFERROR(IF('3 — Weights'!$E$18=1,PERCENTRANK(Y$4:Y$91,Y7),1-PERCENTRANK(Y$4:Y$91,Y7))*100,"") -> 87.3 | AY7: =IFERROR(IF('3 — Weights'!$E$18=1,PERCENTRANK(Z$4:Z$91,Z7),1-PERCENTRANK(Z$4:Z$91,Z7))*100,"") -> 49.5 | AZ7: =IFERROR(IF('3 — Weights'!$E$18=1,PERCENTRANK(AA$4:AA$91,AA7),1-PERCENTRANK(AA$4:AA$91,AA7))*100,"") -> 48.9 | BA7: =IFERROR(IF('3 — Weights'!$E$21=1,PERCENTRANK(AB$4:AB$91,AB7),1-PERCENTRANK(AB$4:AB$91,AB7))*100,"") -> 49.4 | BB7: =IFERROR(IF('3 — Weights'!$E$22=1,PERCENTRANK(AC$4:AC$91,AC7),1-PERCENTRANK(AC$4:AC$91,AC7))*100,"") -> 58.6 | BC7: =IFERROR(IF('3 — Weights'!$E$23=1,PERCENTRANK(AD$4:AD$91,AD7),1-PERCENTRANK(AD$4:AD$91,AD7))*100,"") -> 95.5 | BD7: =IFERROR(IF('3 — Weights'!$E$24=1,PERCENTRANK(AE$4:AE$91,AE7),1-PERCENTRANK(AE$4:AE$91,AE7))*100,"") -> 85.1 | BE7: =IFERROR(IF('3 — Weights'!$E$25=1,PERCENTRANK(AF$4:AF$91,AF7),1-PERCENTRANK(AF$4:AF$91,AF7))*100,"") -> 71.3 | BF7: {=IFERROR(SUMPRODUCT(TRANSPOSE(AH7:BE7), [1]!Table2[Weight Claude]),"")} -> 66.345 | BG7: {=IFERROR(SUMPRODUCT(TRANSPOSE(AH7:BE7), [1]!Table2[Weight Cape IMC]),"")} -> 66.345
A8: =IFERROR(RANK(BG8,BG$4:BG$91),"") -> 5 | B8: WK-US | C8: Workiva Inc. | D8: {=IFERROR(_xll.FDS($B8,"FR_RBICS_NAME_CURR(""IND"")"), "")} -> Enterprise Resource Planning Software | E8: {=PROPER(IFERROR(_xll.FDS($B8,"P_DCOUNTRY"), ""))} -> United States | F8: {=IFERROR(_xll.FDS($B8,"FCS_EV_DAILY(MV,NOW,,,USD,M)"), "")} -> 3464.5608 | G8: {=IFERROR(_xll.FDS($B8,"AVG(P_VOLUME_FRQ(-1AM,NOW,D,,6))*P_PRICE_AVG(-1AM,NOW,,USD)"), "")} -> 79.748816 | H8: {=IFERROR(_xll.FDS($B8,"OS_SEC_FLT_PCT(0D,,MTD,SEC)")/100, "")} -> 0.945492 | I8: {=IFERROR(_xll.FDS($B8,"FE_ACTUAL(ACTUAL,SALES,ANN_ROLL,0,,,,'CURRENCY=USD')"), "")} -> 884.568 | J8: {=IFERROR(_xll.FDS($B8,"FE_ACTUAL(ACTUAL,EPS,ANN_ROLL,0,,,,'CURRENCY=USD')"), "")} -> 1.78 | K8: {=IFERROR(_xll.FDS($B8,"POW(FE_ESTIMATE(SALES,MEAN,STMA,,NOW,,,'CURRENCY=USD')/FE_ESTIMATE(SALES,MEAN,LTMA,,NOW,,,'CURRENCY=USD'),0.5)-1"), "")} -> 0.16463642 | L8: {=IFERROR(_xll.FDS($B8,"POW(FE_ESTIMATE(EPS,MEAN,STMA,,NOW,,,'CURRENCY=USD')/FE_ESTIMATE(EPS,MEAN,LTMA,,NOW,,,'CURRENCY=USD'),0.5)-1"), "")} -> 0.35751335 | M8: {=IFERROR(_xll.FDS($B8,"FF_GROSS_MGN(LTM_R,0)"), "")} -> 78.471977 | N8: {=IFERROR(_xll.FDS($B8,"FF_EBITDA_OPER_MGN(LTM_R,0)"), "")} -> -3.5555209 | O8: {=IFERROR(_xll.FDS($B8,"FF_NET_MGN(LTM_R,0)"), "")} -> -2.9583932 | P8: {=IFERROR(_xll.FDS($B8,"FE_VALUATION(NETDEBT_EBITDA,MEAN,NTMA,,NOW,,,'')"), "")} -> -2.0960221 | Q8: {=IFERROR(_xll.FDS($B8,"FE_VALUATION(MCAP_FCF,MEAN,NTMA,,NOW,,,'')"), "")} -> 6.3010397 | R8: {=IFERROR(_xll.FDS($B8,"FE_VALUATION(DIV_YLD,MEAN,NTMA,,NOW,,,'')"), "")} -> 0 | S8: {=IFERROR(_xll.FDS($B8,"FE_VALUATION(ROE,MEAN,NTMA,,0,,,'')" ), "")} -> 308.23563 | T8: {=IFERROR(_xll.FDS($B8,"FE_VALUATION(ROIC,MEAN,NTMA,,0,,,'')" ), "")} -> 26.25933 | U8: {=IFERROR(((_xll.FDS($B8,"FE_ACTUAL(ACTUAL,SALES,ANN_ROLL,0,,,,'CURRENCY=USD')")/_xll.FDS($B8,"FE_ACTUAL(ACTUAL,SALES,ANN_ROLL,-1,,,,'CURRENCY=USD')")-1)*100)+(_xll.FDS($B8,"FE_VALUATION(EBITDA_MARGIN,MEAN,ANN_ROLL,0,NOW,,,'')") ), "")} -> 30.250543 | V8: {=IFERROR(_xll.FDS($B8,"FE_VALUATION(PE,MEAN,NTMA,,0,,,'')" ), "")} -> 20.549168 | W8: {=IFERROR(_xll.FDS($B8,"FE_VALUATION(P_SALESPS,MEAN,NTMA,,0,,,'')" ), "")} -> 3.087611 | X8: {=IFERROR(_xll.FDS($B8,"FE_VALUATION(FFEV_SALES,MEAN,NTMA,,0,,,'')" ), "")} -> 2.9676418 | Y8: {=IFERROR(_xll.FDS($B8,"FE_VALUATION(FFEV_EBITDA,MEAN,NTMA,,0,,,'')" ), "")} -> 18.165535 | Z8: {=IFERROR(_xll.FDS($B8,"PERCENT_CHANGE(FE_VALUATION(PE,MEAN,NTMA,,0,,,''),MAX(FE_VALUATION(PE,MEAN,NTMA,,-1AY,0,,'')))")/100,"")} -> -0.73145283 | AA8: {=IFERROR(_xll.FDS($B8,"PERCENT_CHANGE(FE_VALUATION(FFEV_EBITDA,MEAN,NTMA,,0,,,''),MAX(FE_VALUATION(FFEV_EBITDA,MEAN,NTMA,,-1AY,0,,'')))")/100,"")} -> -0.77442807 | AB8: {=IFERROR(_xll.FDS($B8,"FG_PRICE(0,,,USD)/P_PRICE_HIGH(-1AY,0,USD,,,""PRICE"",""INTRA"")")-1, "")} -> -0.40573665 | AC8: {=IFERROR(_xll.FDS($B8,"RTP_PRICE_TARGET(USD)/FG_PRICE(0,,,USD)")-1, "")} -> 0.55033872 | AD8: {=IFERROR(_xll.FDS($B8,"FG_PRICE(0,,,USD)/FG_PRICE_MAVG(0,,,USD,50)")-1, "")} -> -0.26861854 | AE8: {=IFERROR(_xll.FDS($B8,"FG_PRICE(0,,,USD)/FG_PRICE_MAVG(0,,,USD,100)")-1, "")} -> -0.31228472 | AF8: {=IFERROR(_xll.FDS($B8,"FG_PRICE(0,,,USD)/FG_PRICE_MAVG(0,,,USD,200)")-1, "")} -> -0.26266315 | AG8: {=IFERROR(_xll.FDS($B8,"FE_RATING(MEAN,TEXTONLY,0,NOW,,,'')"), "")} -> Buy | AH8: =IFERROR(IF('3 — Weights'!$E$2=1,PERCENTRANK(I$4:I$91,I8),1-PERCENTRANK(I$4:I$91,I8))*100,"") -> 27.5 | AI8: =IFERROR(IF('3 — Weights'!$E$3=1,PERCENTRANK(J$4:J$91,J8),1-PERCENTRANK(J$4:J$91,J8))*100,"") -> 42.5 | AJ8: =IFERROR(IF('3 — Weights'!$E$4=1,PERCENTRANK(K$4:K$91,K8),1-PERCENTRANK(K$4:K$91,K8))*100,"") -> 64.3 | AK8: =IFERROR(IF('3 — Weights'!$E$5=1,PERCENTRANK(L$4:L$91,L8),1-PERCENTRANK(L$4:L$91,L8))*100,"") -> 90.4 | AL8: =IFERROR(IF('3 — Weights'!$E$6=1,PERCENTRANK(M$4:M$91,M8),1-PERCENTRANK(M$4:M$91,M8))*100,"") -> 74.3 | AM8: =IFERROR(IF('3 — Weights'!$E$7=1,PERCENTRANK(N$4:N$91,N8),1-PERCENTRANK(N$4:N$91,N8))*100,"") -> 12.9 | AN8: =IFERROR(IF('3 — Weights'!$E$8=1,PERCENTRANK(O$4:O$91,O8),1-PERCENTRANK(O$4:O$91,O8))*100,"") -> 24 | AO8: =IFERROR(IF('3 — Weights'!$E$9=1,PERCENTRANK(P$4:P$91,P8),1-PERCENTRANK(P$4:P$91,P8))*100,"") -> 65.1 | AP8: =IFERROR(IF('3 — Weights'!$E$10=1,PERCENTRANK(Q$4:Q$91,Q8),1-PERCENTRANK(Q$4:Q$91,Q8))*100,"") -> 64.2 | AQ8: =IFERROR(IF('3 — Weights'!$E$11=1,PERCENTRANK(R$4:R$91,R8),1-PERCENTRANK(R$4:R$91,R8))*100,"") -> 0 | AR8: =IFERROR(IF('3 — Weights'!$E$12=1,PERCENTRANK(S$4:S$91,S8),1-PERCENTRANK(S$4:S$91,S8))*100,"") -> 98.7 | AS8: =IFERROR(IF('3 — Weights'!$E$13=1,PERCENTRANK(T$4:T$91,T8),1-PERCENTRANK(T$4:T$91,T8))*100,"") -> 80.5 | AT8: =IFERROR(IF('3 — Weights'!$E$14=1,PERCENTRANK(U$4:U$91,U8),1-PERCENTRANK(U$4:U$91,U8))*100,"") -> 12.1 | AU8: =IFERROR(IF('3 — Weights'!$E$15=1,PERCENTRANK(V$4:V$91,V8),1-PERCENTRANK(V$4:V$91,V8))*100,"") -> 51.8 | AV8: =IFERROR(IF('3 — Weights'!$E$16=1,PERCENTRANK(W$4:W$91,W8),1-PERCENTRANK(W$4:W$91,W8))*100,"") -> 73.6 | AW8: =IFERROR(IF('3 — Weights'!$E$17=1,PERCENTRANK(X$4:X$91,X8),1-PERCENTRANK(X$4:X$91,X8))*100,"") -> 77.1 | AX8: =IFERROR(IF('3 — Weights'!$E$18=1,PERCENTRANK(Y$4:Y$91,Y8),1-PERCENTRANK(Y$4:Y$91,Y8))*100,"") -> 37.3 | AY8: =IFERROR(IF('3 — Weights'!$E$18=1,PERCENTRANK(Z$4:Z$91,Z8),1-PERCENTRANK(Z$4:Z$91,Z8))*100,"") -> 90.9 | AZ8: =IFERROR(IF('3 — Weights'!$E$18=1,PERCENTRANK(AA$4:AA$91,AA8),1-PERCENTRANK(AA$4:AA$91,AA8))*100,"") -> 97.7 | BA8: =IFERROR(IF('3 — Weights'!$E$21=1,PERCENTRANK(AB$4:AB$91,AB8),1-PERCENTRANK(AB$4:AB$91,AB8))*100,"") -> 58.6 | BB8: =IFERROR(IF('3 — Weights'!$E$22=1,PERCENTRANK(AC$4:AC$91,AC8),1-PERCENTRANK(AC$4:AC$91,AC8))*100,"") -> 52.8 | BC8: =IFERROR(IF('3 — Weights'!$E$23=1,PERCENTRANK(AD$4:AD$91,AD8),1-PERCENTRANK(AD$4:AD$91,AD8))*100,"") -> 80.5 | BD8: =IFERROR(IF('3 — Weights'!$E$24=1,PERCENTRANK(AE$4:AE$91,AE8),1-PERCENTRANK(AE$4:AE$91,AE8))*100,"") -> 74.8 | BE8: =IFERROR(IF('3 — Weights'!$E$25=1,PERCENTRANK(AF$4:AF$91,AF8),1-PERCENTRANK(AF$4:AF$91,AF8))*100,"") -> 46 | BF8: {=IFERROR(SUMPRODUCT(TRANSPOSE(AH8:BE8), [1]!Table2[Weight Claude]),"")} -> 64.795 | BG8: {=IFERROR(SUMPRODUCT(TRANSPOSE(AH8:BE8), [1]!Table2[Weight Cape IMC]),"")} -> 64.795
A9: =IFERROR(RANK(BG9,BG$4:BG$91),"") -> 7 | B9: PLTR-US | C9: Palantir Technologies Inc. Class A | D9: {=IFERROR(_xll.FDS($B9,"FR_RBICS_NAME_CURR(""IND"")"), "")} -> Government and Not-For-Profit Industry Software | E9: {=PROPER(IFERROR(_xll.FDS($B9,"P_DCOUNTRY"), ""))} -> United States | F9: {=IFERROR(_xll.FDS($B9,"FCS_EV_DAILY(MV,NOW,,,USD,M)"), "")} -> 331614.85 | G9: {=IFERROR(_xll.FDS($B9,"AVG(P_VOLUME_FRQ(-1AM,NOW,D,,6))*P_PRICE_AVG(-1AM,NOW,,USD)"), "")} -> 7934.6961 | H9: {=IFERROR(_xll.FDS($B9,"OS_SEC_FLT_PCT(0D,,MTD,SEC)")/100, "")} -> 0.954558 | I9: {=IFERROR(_xll.FDS($B9,"FE_ACTUAL(ACTUAL,SALES,ANN_ROLL,0,,,,'CURRENCY=USD')"), "")} -> 4475.446 | J9: {=IFERROR(_xll.FDS($B9,"FE_ACTUAL(ACTUAL,EPS,ANN_ROLL,0,,,,'CURRENCY=USD')"), "")} -> 0.75 | K9: {=IFERROR(_xll.FDS($B9,"POW(FE_ESTIMATE(SALES,MEAN,STMA,,NOW,,,'CURRENCY=USD')/FE_ESTIMATE(SALES,MEAN,LTMA,,NOW,,,'CURRENCY=USD'),0.5)-1"), "")} -> 0.49188126 | L9: {=IFERROR(_xll.FDS($B9,"POW(FE_ESTIMATE(EPS,MEAN,STMA,,NOW,,,'CURRENCY=USD')/FE_ESTIMATE(EPS,MEAN,LTMA,,NOW,,,'CURRENCY=USD'),0.5)-1"), "")} -> 0.52567539 | M9: {=IFERROR(_xll.FDS($B9,"FF_GROSS_MGN(LTM_R,0)"), "")} -> 82.366517 | N9: {=IFERROR(_xll.FDS($B9,"FF_EBITDA_OPER_MGN(LTM_R,0)"), "")} -> 32.179139 | O9: {=IFERROR(_xll.FDS($B9,"FF_NET_MGN(LTM_R,0)"), "")} -> 36.309968 | P9: {=IFERROR(_xll.FDS($B9,"FE_VALUATION(NETDEBT_EBITDA,MEAN,NTMA,,NOW,,,'')"), "")} -> -2.7048798 | Q9: {=IFERROR(_xll.FDS($B9,"FE_VALUATION(MCAP_FCF,MEAN,NTMA,,NOW,,,'')"), "")} -> 1.3955652 | R9: {=IFERROR(_xll.FDS($B9,"FE_VALUATION(DIV_YLD,MEAN,NTMA,,NOW,,,'')"), "")} -> 0 | S9: {=IFERROR(_xll.FDS($B9,"FE_VALUATION(ROE,MEAN,NTMA,,0,,,'')" ), "")} -> 28.090036 | T9: {=IFERROR(_xll.FDS($B9,"FE_VALUATION(ROIC,MEAN,NTMA,,0,,,'')" ), "")} | U9: {=IFERROR(((_xll.FDS($B9,"FE_ACTUAL(ACTUAL,SALES,ANN_ROLL,0,,,,'CURRENCY=USD')")/_xll.FDS($B9,"FE_ACTUAL(ACTUAL,SALES,ANN_ROLL,-1,,,,'CURRENCY=USD')")-1)*100)+(_xll.FDS($B9,"FE_VALUATION(EBITDA_MARGIN,MEAN,ANN_ROLL,0,NOW,,,'')") ), "")} -> 107.1295 | V9: {=IFERROR(_xll.FDS($B9,"FE_VALUATION(PE,MEAN,NTMA,,0,,,'')" ), "")} -> 94.17743 | W9: {=IFERROR(_xll.FDS($B9,"FE_VALUATION(P_SALESPS,MEAN,NTMA,,0,,,'')" ), "")} -> 40.327347 | X9: {=IFERROR(_xll.FDS($B9,"FE_VALUATION(FFEV_SALES,MEAN,NTMA,,0,,,'')" ), "")} -> 42.356777 | Y9: {=IFERROR(_xll.FDS($B9,"FE_VALUATION(FFEV_EBITDA,MEAN,NTMA,,0,,,'')" ), "")} -> 74.32565 | Z9: {=IFERROR(_xll.FDS($B9,"PERCENT_CHANGE(FE_VALUATION(PE,MEAN,NTMA,,0,,,''),MAX(FE_VALUATION(PE,MEAN,NTMA,,-1AY,0,,'')))")/100,"")} -> -0.63115369 | AA9: {=IFERROR(_xll.FDS($B9,"PERCENT_CHANGE(FE_VALUATION(FFEV_EBITDA,MEAN,NTMA,,0,,,''),MAX(FE_VALUATION(FFEV_EBITDA,MEAN,NTMA,,-1AY,0,,'')))")/100,"")} -> -0.63703464 | AB9: {=IFERROR(_xll.FDS($B9,"FG_PRICE(0,,,USD)/P_PRICE_HIGH(-1AY,0,USD,,,""PRICE"",""INTRA"")")-1, "")} -> -0.37914418 | AC9: {=IFERROR(_xll.FDS($B9,"RTP_PRICE_TARGET(USD)/FG_PRICE(0,,,USD)")-1, "")} -> 0.45431481 | AD9: {=IFERROR(_xll.FDS($B9,"FG_PRICE(0,,,USD)/FG_PRICE_MAVG(0,,,USD,50)")-1, "")} -> -0.2144573 | AE9: {=IFERROR(_xll.FDS($B9,"FG_PRICE(0,,,USD)/FG_PRICE_MAVG(0,,,USD,100)")-1, "")} -> -0.24982128 | AF9: {=IFERROR(_xll.FDS($B9,"FG_PRICE(0,,,USD)/FG_PRICE_MAVG(0,,,USD,200)")-1, "")} -> -0.20094255 | AG9: {=IFERROR(_xll.FDS($B9,"FE_RATING(MEAN,TEXTONLY,0,NOW,,,'')"), "")} -> Overweight | AH9: =IFERROR(IF('3 — Weights'!$E$2=1,PERCENTRANK(I$4:I$91,I9),1-PERCENTRANK(I$4:I$91,I9))*100,"") -> 74.7 | AI9: =IFERROR(IF('3 — Weights'!$E$3=1,PERCENTRANK(J$4:J$91,J9),1-PERCENTRANK(J$4:J$91,J9))*100,"") -> 28.7 | AJ9: =IFERROR(IF('3 — Weights'!$E$4=1,PERCENTRANK(K$4:K$91,K9),1-PERCENTRANK(K$4:K$91,K9))*100,"") -> 98.8 | AK9: =IFERROR(IF('3 — Weights'!$E$5=1,PERCENTRANK(L$4:L$91,L9),1-PERCENTRANK(L$4:L$91,L9))*100,"") -> 96.4 | AL9: =IFERROR(IF('3 — Weights'!$E$6=1,PERCENTRANK(M$4:M$91,M9),1-PERCENTRANK(M$4:M$91,M9))*100,"") -> 86.5 | AM9: =IFERROR(IF('3 — Weights'!$E$7=1,PERCENTRANK(N$4:N$91,N9),1-PERCENTRANK(N$4:N$91,N9))*100,"") -> 79.2 | AN9: =IFERROR(IF('3 — Weights'!$E$8=1,PERCENTRANK(O$4:O$91,O9),1-PERCENTRANK(O$4:O$91,O9))*100,"") -> 93.9 | AO9: =IFERROR(IF('3 — Weights'!$E$9=1,PERCENTRANK(P$4:P$91,P9),1-PERCENTRANK(P$4:P$91,P9))*100,"") -> 77.2 | AP9: =IFERROR(IF('3 — Weights'!$E$10=1,PERCENTRANK(Q$4:Q$91,Q9),1-PERCENTRANK(Q$4:Q$91,Q9))*100,"") -> 5.9 | AQ9: =IFERROR(IF('3 — Weights'!$E$11=1,PERCENTRANK(R$4:R$91,R9),1-PERCENTRANK(R$4:R$91,R9))*100,"") -> 0 | AR9: =IFERROR(IF('3 — Weights'!$E$12=1,PERCENTRANK(S$4:S$91,S9),1-PERCENTRANK(S$4:S$91,S9))*100,"") -> 74 | AS9: =IFERROR(IF('3 — Weights'!$E$13=1,PERCENTRANK(T$4:T$91,T9),1-PERCENTRANK(T$4:T$91,T9))*100,"") | AT9: =IFERROR(IF('3 — Weights'!$E$14=1,PERCENTRANK(U$4:U$91,U9),1-PERCENTRANK(U$4:U$91,U9))*100,"") -> 98.7 | AU9: =IFERROR(IF('3 — Weights'!$E$15=1,PERCENTRANK(V$4:V$91,V9),1-PERCENTRANK(V$4:V$91,V9))*100,"") -> 8.1 | AV9: =IFERROR(IF('3 — Weights'!$E$16=1,PERCENTRANK(W$4:W$91,W9),1-PERCENTRANK(W$4:W$91,W9))*100,"") -> 1.2 | AW9: =IFERROR(IF('3 — Weights'!$E$17=1,PERCENTRANK(X$4:X$91,X9),1-PERCENTRANK(X$4:X$91,X9))*100,"") -> 1.2 | AX9: =IFERROR(IF('3 — Weights'!$E$18=1,PERCENTRANK(Y$4:Y$91,Y9),1-PERCENTRANK(Y$4:Y$91,Y9))*100,"") -> 3.5 | AY9: =IFERROR(IF('3 — Weights'!$E$18=1,PERCENTRANK(Z$4:Z$91,Z9),1-PERCENTRANK(Z$4:Z$91,Z9))*100,"") -> 82.8 | AZ9: =IFERROR(IF('3 — Weights'!$E$18=1,PERCENTRANK(AA$4:AA$91,AA9),1-PERCENTRANK(AA$4:AA$91,AA9))*100,"") -> 82.6 | BA9: =IFERROR(IF('3 — Weights'!$E$21=1,PERCENTRANK(AB$4:AB$91,AB9),1-PERCENTRANK(AB$4:AB$91,AB9))*100,"") -> 67.8 | BB9: =IFERROR(IF('3 — Weights'!$E$22=1,PERCENTRANK(AC$4:AC$91,AC9),1-PERCENTRANK(AC$4:AC$91,AC9))*100,"") -> 40.2 | BC9: =IFERROR(IF('3 — Weights'!$E$23=1,PERCENTRANK(AD$4:AD$91,AD9),1-PERCENTRANK(AD$4:AD$91,AD9))*100,"") -> 65.6 | BD9: =IFERROR(IF('3 — Weights'!$E$24=1,PERCENTRANK(AE$4:AE$91,AE9),1-PERCENTRANK(AE$4:AE$91,AE9))*100,"") -> 48.3 | BE9: =IFERROR(IF('3 — Weights'!$E$25=1,PERCENTRANK(AF$4:AF$91,AF9),1-PERCENTRANK(AF$4:AF$91,AF9))*100,"") -> 29.9 | BF9: {=IFERROR(SUMPRODUCT(TRANSPOSE(AH9:BE9), [1]!Table2[Weight Claude]),"")} -> 61.155 | BG9: {=IFERROR(SUMPRODUCT(TRANSPOSE(AH9:BE9), [1]!Table2[Weight Cape IMC]),"")} -> 61.155
A10: =IFERROR(RANK(BG10,BG$4:BG$91),"") -> 9 | B10: DT-US | C10: Dynatrace, Inc. | D10: {=IFERROR(_xll.FDS($B10,"FR_RBICS_NAME_CURR(""IND"")"), "")} -> Network Infrastructure Software | E10: {=PROPER(IFERROR(_xll.FDS($B10,"P_DCOUNTRY"), ""))} -> United States | F10: {=IFERROR(_xll.FDS($B10,"FCS_EV_DAILY(MV,NOW,,,USD,M)"), "")} -> 10620.581 | G10: {=IFERROR(_xll.FDS($B10,"AVG(P_VOLUME_FRQ(-1AM,NOW,D,,6))*P_PRICE_AVG(-1AM,NOW,,USD)"), "")} -> 235.06203 | H10: {=IFERROR(_xll.FDS($B10,"OS_SEC_FLT_PCT(0D,,MTD,SEC)")/100, "")} -> 0.988897 | I10: {=IFERROR(_xll.FDS($B10,"FE_ACTUAL(ACTUAL,SALES,ANN_ROLL,0,,,,'CURRENCY=USD')"), "")} -> 1698.683 | J10: {=IFERROR(_xll.FDS($B10,"FE_ACTUAL(ACTUAL,EPS,ANN_ROLL,0,,,,'CURRENCY=USD')"), "")} -> 1.39 | K10: {=IFERROR(_xll.FDS($B10,"POW(FE_ESTIMATE(SALES,MEAN,STMA,,NOW,,,'CURRENCY=USD')/FE_ESTIMATE(SALES,MEAN,LTMA,,NOW,,,'CURRENCY=USD'),0.5)-1"), "")} -> 0.14754063 | L10: {=IFERROR(_xll.FDS($B10,"POW(FE_ESTIMATE(EPS,MEAN,STMA,,NOW,,,'CURRENCY=USD')/FE_ESTIMATE(EPS,MEAN,LTMA,,NOW,,,'CURRENCY=USD'),0.5)-1"), "")} -> 0.14545838 | M10: {=IFERROR(_xll.FDS($B10,"FF_GROSS_MGN(LTM_R,0)"), "")} -> 81.574419 | N10: {=IFERROR(_xll.FDS($B10,"FF_EBITDA_OPER_MGN(LTM_R,0)"), "")} -> 14.261511 | O10: {=IFERROR(_xll.FDS($B10,"FF_NET_MGN(LTM_R,0)"), "")} -> 9.5534507 | P10: {=IFERROR(_xll.FDS($B10,"FE_VALUATION(NETDEBT_EBITDA,MEAN,NTMA,,NOW,,,'')"), "")} -> -2.5842223 | Q10: {=IFERROR(_xll.FDS($B10,"FE_VALUATION(MCAP_FCF,MEAN,NTMA,,NOW,,,'')"), "")} -> 5.884752 | R10: {=IFERROR(_xll.FDS($B10,"FE_VALUATION(DIV_YLD,MEAN,NTMA,,NOW,,,'')"), "")} -> 0 | S10: {=IFERROR(_xll.FDS($B10,"FE_VALUATION(ROE,MEAN,NTMA,,0,,,'')" ), "")} -> 17.984053 | T10: {=IFERROR(_xll.FDS($B10,"FE_VALUATION(ROIC,MEAN,NTMA,,0,,,'')" ), "")} -> 16.54999 | U10: {=IFERROR(((_xll.FDS($B10,"FE_ACTUAL(ACTUAL,SALES,ANN_ROLL,0,,,,'CURRENCY=USD')")/_xll.FDS($B10,"FE_ACTUAL(ACTUAL,SALES,ANN_ROLL,-1,,,,'CURRENCY=USD')")-1)*100)+(_xll.FDS($B10,"FE_VALUATION(EBITDA_MARGIN,MEAN,ANN_ROLL,0,NOW,,,'')") ), "")} -> 49.576971 | V10: {=IFERROR(_xll.FDS($B10,"FE_VALUATION(PE,MEAN,NTMA,,0,,,'')" ), "")} -> 18.10821 | W10: {=IFERROR(_xll.FDS($B10,"FE_VALUATION(P_SALESPS,MEAN,NTMA,,0,,,'')" ), "")} -> 4.487807 | X10: {=IFERROR(_xll.FDS($B10,"FE_VALUATION(FFEV_SALES,MEAN,NTMA,,0,,,'')" ), "")} -> 4.078665 | Y10: {=IFERROR(_xll.FDS($B10,"FE_VALUATION(FFEV_EBITDA,MEAN,NTMA,,0,,,'')" ), "")} -> 13.261618 | Z10: {=IFERROR(_xll.FDS($B10,"PERCENT_CHANGE(FE_VALUATION(PE,MEAN,NTMA,,0,,,''),MAX(FE_VALUATION(PE,MEAN,NTMA,,-1AY,0,,'')))")/100,"")} -> -0.53002122 | AA10: {=IFERROR(_xll.FDS($B10,"PERCENT_CHANGE(FE_VALUATION(FFEV_EBITDA,MEAN,NTMA,,0,,,''),MAX(FE_VALUATION(FFEV_EBITDA,MEAN,NTMA,,-1AY,0,,'')))")/100,"")} -> -0.54523905 | AB10: {=IFERROR(_xll.FDS($B10,"FG_PRICE(0,,,USD)/P_PRICE_HIGH(-1AY,0,USD,,,""PRICE"",""INTRA"")")-1, "")} -> -0.43011647 | AC10: {=IFERROR(_xll.FDS($B10,"RTP_PRICE_TARGET(USD)/FG_PRICE(0,,,USD)")-1, "")} -> 0.46082724 | AD10: {=IFERROR(_xll.FDS($B10,"FG_PRICE(0,,,USD)/FG_PRICE_MAVG(0,,,USD,50)")-1, "")} -> -0.14760708 | AE10: {=IFERROR(_xll.FDS($B10,"FG_PRICE(0,,,USD)/FG_PRICE_MAVG(0,,,USD,100)")-1, "")} -> -0.21662538 | AF10: {=IFERROR(_xll.FDS($B10,"FG_PRICE(0,,,USD)/FG_PRICE_MAVG(0,,,USD,200)")-1, "")} -> -0.28230542 | AG10: {=IFERROR(_xll.FDS($B10,"FE_RATING(MEAN,TEXTONLY,0,NOW,,,'')"), "")} -> Overweight | AH10: =IFERROR(IF('3 — Weights'!$E$2=1,PERCENTRANK(I$4:I$91,I10),1-PERCENTRANK(I$4:I$91,I10))*100,"") -> 51.7 | AI10: =IFERROR(IF('3 — Weights'!$E$3=1,PERCENTRANK(J$4:J$91,J10),1-PERCENTRANK(J$4:J$91,J10))*100,"") -> 37.9 | AJ10: =IFERROR(IF('3 — Weights'!$E$4=1,PERCENTRANK(K$4:K$91,K10),1-PERCENTRANK(K$4:K$91,K10))*100,"") -> 57.4 | AK10: =IFERROR(IF('3 — Weights'!$E$5=1,PERCENTRANK(L$4:L$91,L10),1-PERCENTRANK(L$4:L$91,L10))*100,"") -> 39.2 | AL10: =IFERROR(IF('3 — Weights'!$E$6=1,PERCENTRANK(M$4:M$91,M10),1-PERCENTRANK(M$4:M$91,M10))*100,"") -> 82.9 | AM10: =IFERROR(IF('3 — Weights'!$E$7=1,PERCENTRANK(N$4:N$91,N10),1-PERCENTRANK(N$4:N$91,N10))*100,"") -> 41.5 | AN10: =IFERROR(IF('3 — Weights'!$E$8=1,PERCENTRANK(O$4:O$91,O10),1-PERCENTRANK(O$4:O$91,O10))*100,"") -> 45.7 | AO10: =IFERROR(IF('3 — Weights'!$E$9=1,PERCENTRANK(P$4:P$91,P10),1-PERCENTRANK(P$4:P$91,P10))*100,"") -> 76 | AP10: =IFERROR(IF('3 — Weights'!$E$10=1,PERCENTRANK(Q$4:Q$91,Q10),1-PERCENTRANK(Q$4:Q$91,Q10))*100,"") -> 60.7 | AQ10: =IFERROR(IF('3 — Weights'!$E$11=1,PERCENTRANK(R$4:R$91,R10),1-PERCENTRANK(R$4:R$91,R10))*100,"") -> 0 | AR10: =IFERROR(IF('3 — Weights'!$E$12=1,PERCENTRANK(S$4:S$91,S10),1-PERCENTRANK(S$4:S$91,S10))*100,"") -> 40.7 | AS10: =IFERROR(IF('3 — Weights'!$E$13=1,PERCENTRANK(T$4:T$91,T10),1-PERCENTRANK(T$4:T$91,T10))*100,"") -> 50 | AT10: =IFERROR(IF('3 — Weights'!$E$14=1,PERCENTRANK(U$4:U$91,U10),1-PERCENTRANK(U$4:U$91,U10))*100,"") -> 60.9 | AU10: =IFERROR(IF('3 — Weights'!$E$15=1,PERCENTRANK(V$4:V$91,V10),1-PERCENTRANK(V$4:V$91,V10))*100,"") -> 64.4 | AV10: =IFERROR(IF('3 — Weights'!$E$16=1,PERCENTRANK(W$4:W$91,W10),1-PERCENTRANK(W$4:W$91,W10))*100,"") -> 51.8 | AW10: =IFERROR(IF('3 — Weights'!$E$17=1,PERCENTRANK(X$4:X$91,X10),1-PERCENTRANK(X$4:X$91,X10))*100,"") -> 57.5 | AX10: =IFERROR(IF('3 — Weights'!$E$18=1,PERCENTRANK(Y$4:Y$91,Y10),1-PERCENTRANK(Y$4:Y$91,Y10))*100,"") -> 61.7 | AY10: =IFERROR(IF('3 — Weights'!$E$18=1,PERCENTRANK(Z$4:Z$91,Z10),1-PERCENTRANK(Z$4:Z$91,Z10))*100,"") -> 54.1 | AZ10: =IFERROR(IF('3 — Weights'!$E$18=1,PERCENTRANK(AA$4:AA$91,AA10),1-PERCENTRANK(AA$4:AA$91,AA10))*100,"") -> 57 | BA10: =IFERROR(IF('3 — Weights'!$E$21=1,PERCENTRANK(AB$4:AB$91,AB10),1-PERCENTRANK(AB$4:AB$91,AB10))*100,"") -> 52.8 | BB10: =IFERROR(IF('3 — Weights'!$E$22=1,PERCENTRANK(AC$4:AC$91,AC10),1-PERCENTRANK(AC$4:AC$91,AC10))*100,"") -> 43.6 | BC10: =IFERROR(IF('3 — Weights'!$E$23=1,PERCENTRANK(AD$4:AD$91,AD10),1-PERCENTRANK(AD$4:AD$91,AD10))*100,"") -> 33.4 | BD10: =IFERROR(IF('3 — Weights'!$E$24=1,PERCENTRANK(AE$4:AE$91,AE10),1-PERCENTRANK(AE$4:AE$91,AE10))*100,"") -> 36.8 | BE10: =IFERROR(IF('3 — Weights'!$E$25=1,PERCENTRANK(AF$4:AF$91,AF10),1-PERCENTRANK(AF$4:AF$91,AF10))*100,"") -> 49.5 | BF10: {=IFERROR(SUMPRODUCT(TRANSPOSE(AH10:BE10), [1]!Table2[Weight Claude]),"")} -> 60.77 | BG10: {=IFERROR(SUMPRODUCT(TRANSPOSE(AH10:BE10), [1]!Table2[Weight Cape IMC]),"")} -> 60.77
A11: =IFERROR(RANK(BG11,BG$4:BG$91),"") -> 8 | B11: NOW-US | C11: ServiceNow, Inc. | D11: {=IFERROR(_xll.FDS($B11,"FR_RBICS_NAME_CURR(""IND"")"), "")} -> General Enterprise Management Software | E11: {=PROPER(IFERROR(_xll.FDS($B11,"P_DCOUNTRY"), ""))} -> United States | F11: {=IFERROR(_xll.FDS($B11,"FCS_EV_DAILY(MV,NOW,,,USD,M)"), "")} -> 109870.41 | G11: {=IFERROR(_xll.FDS($B11,"AVG(P_VOLUME_FRQ(-1AM,NOW,D,,6))*P_PRICE_AVG(-1AM,NOW,,USD)"), "")} -> 2659.886 | H11: {=IFERROR(_xll.FDS($B11,"OS_SEC_FLT_PCT(0D,,MTD,SEC)")/100, "")} -> 0.993365 | I11: {=IFERROR(_xll.FDS($B11,"FE_ACTUAL(ACTUAL,SALES,ANN_ROLL,0,,,,'CURRENCY=USD')"), "")} -> 13278 | J11: {=IFERROR(_xll.FDS($B11,"FE_ACTUAL(ACTUAL,EPS,ANN_ROLL,0,,,,'CURRENCY=USD')"), "")} -> 3.51 | K11: {=IFERROR(_xll.FDS($B11,"POW(FE_ESTIMATE(SALES,MEAN,STMA,,NOW,,,'CURRENCY=USD')/FE_ESTIMATE(SALES,MEAN,LTMA,,NOW,,,'CURRENCY=USD'),0.5)-1"), "")} -> 0.19397127 | L11: {=IFERROR(_xll.FDS($B11,"POW(FE_ESTIMATE(EPS,MEAN,STMA,,NOW,,,'CURRENCY=USD')/FE_ESTIMATE(EPS,MEAN,LTMA,,NOW,,,'CURRENCY=USD'),0.5)-1"), "")} -> 0.20121788 | M11: {=IFERROR(_xll.FDS($B11,"FF_GROSS_MGN(LTM_R,0)"), "")} -> 77.534267 | N11: {=IFERROR(_xll.FDS($B11,"FF_EBITDA_OPER_MGN(LTM_R,0)"), "")} -> 19.596325 | O11: {=IFERROR(_xll.FDS($B11,"FF_NET_MGN(LTM_R,0)"), "")} -> 13.164633 | P11: {=IFERROR(_xll.FDS($B11,"FE_VALUATION(NETDEBT_EBITDA,MEAN,NTMA,,NOW,,,'')"), "")} -> -1.4570582 | Q11: {=IFERROR(_xll.FDS($B11,"FE_VALUATION(MCAP_FCF,MEAN,NTMA,,NOW,,,'')"), "")} -> 5.4903965 | R11: {=IFERROR(_xll.FDS($B11,"FE_VALUATION(DIV_YLD,MEAN,NTMA,,NOW,,,'')"), "")} -> 0 | S11: {=IFERROR(_xll.FDS($B11,"FE_VALUATION(ROE,MEAN,NTMA,,0,,,'')" ), "")} -> 27.540297 | T11: {=IFERROR(_xll.FDS($B11,"FE_VALUATION(ROIC,MEAN,NTMA,,0,,,'')" ), "")} -> 24.644463 | U11: {=IFERROR(((_xll.FDS($B11,"FE_ACTUAL(ACTUAL,SALES,ANN_ROLL,0,,,,'CURRENCY=USD')")/_xll.FDS($B11,"FE_ACTUAL(ACTUAL,SALES,ANN_ROLL,-1,,,,'CURRENCY=USD')")-1)*100)+(_xll.FDS($B11,"FE_VALUATION(EBITDA_MARGIN,MEAN,ANN_ROLL,0,NOW,,,'')") ), "")} -> 58.205637 | V11: {=IFERROR(_xll.FDS($B11,"FE_VALUATION(PE,MEAN,NTMA,,0,,,'')" ), "")} -> 23.757355 | W11: {=IFERROR(_xll.FDS($B11,"FE_VALUATION(P_SALESPS,MEAN,NTMA,,0,,,'')" ), "")} -> 6.5305815 | X11: {=IFERROR(_xll.FDS($B11,"FE_VALUATION(FFEV_SALES,MEAN,NTMA,,0,,,'')" ), "")} -> 6.2981114 | Y11: {=IFERROR(_xll.FDS($B11,"FE_VALUATION(FFEV_EBITDA,MEAN,NTMA,,0,,,'')" ), "")} -> 17.151566 | Z11: {=IFERROR(_xll.FDS($B11,"PERCENT_CHANGE(FE_VALUATION(PE,MEAN,NTMA,,0,,,''),MAX(FE_VALUATION(PE,MEAN,NTMA,,-1AY,0,,'')))")/100,"")} -> -0.59356938 | AA11: {=IFERROR(_xll.FDS($B11,"PERCENT_CHANGE(FE_VALUATION(FFEV_EBITDA,MEAN,NTMA,,0,,,''),MAX(FE_VALUATION(FFEV_EBITDA,MEAN,NTMA,,-1AY,0,,'')))")/100,"")} -> -0.60575563 | AB11: {=IFERROR(_xll.FDS($B11,"FG_PRICE(0,,,USD)/P_PRICE_HIGH(-1AY,0,USD,,,""PRICE"",""INTRA"")")-1, "")} -> -0.51536325 | AC11: {=IFERROR(_xll.FDS($B11,"RTP_PRICE_TARGET(USD)/FG_PRICE(0,,,USD)")-1, "")} -> 0.83132306 | AD11: {=IFERROR(_xll.FDS($B11,"FG_PRICE(0,,,USD)/FG_PRICE_MAVG(0,,,USD,50)")-1, "")} -> -0.22275533 | AE11: {=IFERROR(_xll.FDS($B11,"FG_PRICE(0,,,USD)/FG_PRICE_MAVG(0,,,USD,100)")-1, "")} -> -0.33323809 | AF11: {=IFERROR(_xll.FDS($B11,"FG_PRICE(0,,,USD)/FG_PRICE_MAVG(0,,,USD,200)")-1, "")} -> -0.40764628 | AG11: {=IFERROR(_xll.FDS($B11,"FE_RATING(MEAN,TEXTONLY,0,NOW,,,'')"), "")} -> Buy | AH11: =IFERROR(IF('3 — Weights'!$E$2=1,PERCENTRANK(I$4:I$91,I11),1-PERCENTRANK(I$4:I$91,I11))*100,"") -> 94.2 | AI11: =IFERROR(IF('3 — Weights'!$E$3=1,PERCENTRANK(J$4:J$91,J11),1-PERCENTRANK(J$4:J$91,J11))*100,"") -> 60.9 | AJ11: =IFERROR(IF('3 — Weights'!$E$4=1,PERCENTRANK(K$4:K$91,K11),1-PERCENTRANK(K$4:K$91,K11))*100,"") -> 81.6 | AK11: =IFERROR(IF('3 — Weights'!$E$5=1,PERCENTRANK(L$4:L$91,L11),1-PERCENTRANK(L$4:L$91,L11))*100,"") -> 66.6 | AL11: =IFERROR(IF('3 — Weights'!$E$6=1,PERCENTRANK(M$4:M$91,M11),1-PERCENTRANK(M$4:M$91,M11))*100,"") -> 69.5 | AM11: =IFERROR(IF('3 — Weights'!$E$7=1,PERCENTRANK(N$4:N$91,N11),1-PERCENTRANK(N$4:N$91,N11))*100,"") -> 50.6 | AN11: =IFERROR(IF('3 — Weights'!$E$8=1,PERCENTRANK(O$4:O$91,O11),1-PERCENTRANK(O$4:O$91,O11))*100,"") -> 59 | AO11: =IFERROR(IF('3 — Weights'!$E$9=1,PERCENTRANK(P$4:P$91,P11),1-PERCENTRANK(P$4:P$91,P11))*100,"") -> 57.9 | AP11: =IFERROR(IF('3 — Weights'!$E$10=1,PERCENTRANK(Q$4:Q$91,Q11),1-PERCENTRANK(Q$4:Q$91,Q11))*100,"") -> 55.9 | AQ11: =IFERROR(IF('3 — Weights'!$E$11=1,PERCENTRANK(R$4:R$91,R11),1-PERCENTRANK(R$4:R$91,R11))*100,"") -> 0 | AR11: =IFERROR(IF('3 — Weights'!$E$12=1,PERCENTRANK(S$4:S$91,S11),1-PERCENTRANK(S$4:S$91,S11))*100,"") -> 69.1 | AS11: =IFERROR(IF('3 — Weights'!$E$13=1,PERCENTRANK(T$4:T$91,T11),1-PERCENTRANK(T$4:T$91,T11))*100,"") -> 76.3 | AT11: =IFERROR(IF('3 — Weights'!$E$14=1,PERCENTRANK(U$4:U$91,U11),1-PERCENTRANK(U$4:U$91,U11))*100,"") -> 80.4 | AU11: =IFERROR(IF('3 — Weights'!$E$15=1,PERCENTRANK(V$4:V$91,V11),1-PERCENTRANK(V$4:V$91,V11))*100,"") -> 43.7 | AV11: =IFERROR(IF('3 — Weights'!$E$16=1,PERCENTRANK(W$4:W$91,W11),1-PERCENTRANK(W$4:W$91,W11))*100,"") -> 29.9 | AW11: =IFERROR(IF('3 — Weights'!$E$17=1,PERCENTRANK(X$4:X$91,X11),1-PERCENTRANK(X$4:X$91,X11))*100,"") -> 32.2 | AX11: =IFERROR(IF('3 — Weights'!$E$18=1,PERCENTRANK(Y$4:Y$91,Y11),1-PERCENTRANK(Y$4:Y$91,Y11))*100,"") -> 41.9 | AY11: =IFERROR(IF('3 — Weights'!$E$18=1,PERCENTRANK(Z$4:Z$91,Z11),1-PERCENTRANK(Z$4:Z$91,Z11))*100,"") -> 71.3 | AZ11: =IFERROR(IF('3 — Weights'!$E$18=1,PERCENTRANK(AA$4:AA$91,AA11),1-PERCENTRANK(AA$4:AA$91,AA11))*100,"") -> 78 | BA11: =IFERROR(IF('3 — Weights'!$E$21=1,PERCENTRANK(AB$4:AB$91,AB11),1-PERCENTRANK(AB$4:AB$91,AB11))*100,"") -> 24.1 | BB11: =IFERROR(IF('3 — Weights'!$E$22=1,PERCENTRANK(AC$4:AC$91,AC11),1-PERCENTRANK(AC$4:AC$91,AC11))*100,"") -> 82.7 | BC11: =IFERROR(IF('3 — Weights'!$E$23=1,PERCENTRANK(AD$4:AD$91,AD11),1-PERCENTRANK(AD$4:AD$91,AD11))*100,"") -> 70.2 | BD11: =IFERROR(IF('3 — Weights'!$E$24=1,PERCENTRANK(AE$4:AE$91,AE11),1-PERCENTRANK(AE$4:AE$91,AE11))*100,"") -> 82.8 | BE11: =IFERROR(IF('3 — Weights'!$E$25=1,PERCENTRANK(AF$4:AF$91,AF11),1-PERCENTRANK(AF$4:AF$91,AF11))*100,"") -> 84 | BF11: {=IFERROR(SUMPRODUCT(TRANSPOSE(AH11:BE11), [1]!Table2[Weight Claude]),"")} -> 60.795 | BG11: {=IFERROR(SUMPRODUCT(TRANSPOSE(AH11:BE11), [1]!Table2[Weight Cape IMC]),"")} -> 60.795
A12: =IFERROR(RANK(BG12,BG$4:BG$91),"") -> 10 | B12: TENB-US | C12: Tenable Holdings, Inc. | D12: {=IFERROR(_xll.FDS($B12,"FR_RBICS_NAME_CURR(""IND"")"), "")} -> Network Infrastructure Software | E12: {=PROPER(IFERROR(_xll.FDS($B12,"P_DCOUNTRY"), ""))} -> United States | F12: {=IFERROR(_xll.FDS($B12,"FCS_EV_DAILY(MV,NOW,,,USD,M)"), "")} -> 2365.7286 | G12: {=IFERROR(_xll.FDS($B12,"AVG(P_VOLUME_FRQ(-1AM,NOW,D,,6))*P_PRICE_AVG(-1AM,NOW,,USD)"), "")} -> 69.851512 | H12: {=IFERROR(_xll.FDS($B12,"OS_SEC_FLT_PCT(0D,,MTD,SEC)")/100, "")} -> 0.97952 | I12: {=IFERROR(_xll.FDS($B12,"FE_ACTUAL(ACTUAL,SALES,ANN_ROLL,0,,,,'CURRENCY=USD')"), "")} -> 999.405 | J12: {=IFERROR(_xll.FDS($B12,"FE_ACTUAL(ACTUAL,EPS,ANN_ROLL,0,,,,'CURRENCY=USD')"), "")} -> 1.59 | K12: {=IFERROR(_xll.FDS($B12,"POW(FE_ESTIMATE(SALES,MEAN,STMA,,NOW,,,'CURRENCY=USD')/FE_ESTIMATE(SALES,MEAN,LTMA,,NOW,,,'CURRENCY=USD'),0.5)-1"), "")} -> 0.071790185 | L12: {=IFERROR(_xll.FDS($B12,"POW(FE_ESTIMATE(EPS,MEAN,STMA,,NOW,,,'CURRENCY=USD')/FE_ESTIMATE(EPS,MEAN,LTMA,,NOW,,,'CURRENCY=USD'),0.5)-1"), "")} -> 0.14481693 | M12: {=IFERROR(_xll.FDS($B12,"FF_GROSS_MGN(LTM_R,0)"), "")} -> 81.955464 | N12: {=IFERROR(_xll.FDS($B12,"FF_EBITDA_OPER_MGN(LTM_R,0)"), "")} -> 4.3181693 | O12: {=IFERROR(_xll.FDS($B12,"FF_NET_MGN(LTM_R,0)"), "")} -> -3.6139503 | P12: {=IFERROR(_xll.FDS($B12,"FE_VALUATION(NETDEBT_EBITDA,MEAN,NTMA,,NOW,,,'')"), "")} -> -0.88758624 | Q12: {=IFERROR(_xll.FDS($B12,"FE_VALUATION(MCAP_FCF,MEAN,NTMA,,NOW,,,'')"), "")} -> 12.433495 | R12: {=IFERROR(_xll.FDS($B12,"FE_VALUATION(DIV_YLD,MEAN,NTMA,,NOW,,,'')"), "")} -> 0 | S12: {=IFERROR(_xll.FDS($B12,"FE_VALUATION(ROE,MEAN,NTMA,,0,,,'')" ), "")} -> 46.280136 | T12: {=IFERROR(_xll.FDS($B12,"FE_VALUATION(ROIC,MEAN,NTMA,,0,,,'')" ), "")} -> 26.39757 | U12: {=IFERROR(((_xll.FDS($B12,"FE_ACTUAL(ACTUAL,SALES,ANN_ROLL,0,,,,'CURRENCY=USD')")/_xll.FDS($B12,"FE_ACTUAL(ACTUAL,SALES,ANN_ROLL,-1,,,,'CURRENCY=USD')")-1)*100)+(_xll.FDS($B12,"FE_VALUATION(EBITDA_MARGIN,MEAN,ANN_ROLL,0,NOW,,,'')") ), "")} -> 34.589799 | V12: {=IFERROR(_xll.FDS($B12,"FE_VALUATION(PE,MEAN,NTMA,,0,,,'')" ), "")} -> 9.616364 | W12: {=IFERROR(_xll.FDS($B12,"FE_VALUATION(P_SALESPS,MEAN,NTMA,,0,,,'')" ), "")} -> 2.016584 | X12: {=IFERROR(_xll.FDS($B12,"FE_VALUATION(FFEV_SALES,MEAN,NTMA,,0,,,'')" ), "")} -> 2.0413074 | Y12: {=IFERROR(_xll.FDS($B12,"FE_VALUATION(FFEV_EBITDA,MEAN,NTMA,,0,,,'')" ), "")} -> 8.11703 | Z12: {=IFERROR(_xll.FDS($B12,"PERCENT_CHANGE(FE_VALUATION(PE,MEAN,NTMA,,0,,,''),MAX(FE_VALUATION(PE,MEAN,NTMA,,-1AY,0,,'')))")/100,"")} -> -0.61633428 | AA12: {=IFERROR(_xll.FDS($B12,"PERCENT_CHANGE(FE_VALUATION(FFEV_EBITDA,MEAN,NTMA,,0,,,''),MAX(FE_VALUATION(FFEV_EBITDA,MEAN,NTMA,,-1AY,0,,'')))")/100,"")} -> -0.56193107 | AB12: {=IFERROR(_xll.FDS($B12,"FG_PRICE(0,,,USD)/P_PRICE_HIGH(-1AY,0,USD,,,""PRICE"",""INTRA"")")-1, "")} -> -0.53252396 | AC12: {=IFERROR(_xll.FDS($B12,"RTP_PRICE_TARGET(USD)/FG_PRICE(0,,,USD)")-1, "")} -> 0.67972777 | AD12: {=IFERROR(_xll.FDS($B12,"FG_PRICE(0,,,USD)/FG_PRICE_MAVG(0,,,USD,50)")-1, "")} -> -0.19493279 | AE12: {=IFERROR(_xll.FDS($B12,"FG_PRICE(0,,,USD)/FG_PRICE_MAVG(0,,,USD,100)")-1, "")} -> -0.27975538 | AF12: {=IFERROR(_xll.FDS($B12,"FG_PRICE(0,,,USD)/FG_PRICE_MAVG(0,,,USD,200)")-1, "")} -> -0.3595445 | AG12: {=IFERROR(_xll.FDS($B12,"FE_RATING(MEAN,TEXTONLY,0,NOW,,,'')"), "")} -> Overweight | AH12: =IFERROR(IF('3 — Weights'!$E$2=1,PERCENTRANK(I$4:I$91,I12),1-PERCENTRANK(I$4:I$91,I12))*100,"") -> 32.1 | AI12: =IFERROR(IF('3 — Weights'!$E$3=1,PERCENTRANK(J$4:J$91,J12),1-PERCENTRANK(J$4:J$91,J12))*100,"") -> 41.3 | AJ12: =IFERROR(IF('3 — Weights'!$E$4=1,PERCENTRANK(K$4:K$91,K12),1-PERCENTRANK(K$4:K$91,K12))*100,"") -> 17.2 | AK12: =IFERROR(IF('3 — Weights'!$E$5=1,PERCENTRANK(L$4:L$91,L12),1-PERCENTRANK(L$4:L$91,L12))*100,"") -> 38 | AL12: =IFERROR(IF('3 — Weights'!$E$6=1,PERCENTRANK(M$4:M$91,M12),1-PERCENTRANK(M$4:M$91,M12))*100,"") -> 84.1 | AM12: =IFERROR(IF('3 — Weights'!$E$7=1,PERCENTRANK(N$4:N$91,N12),1-PERCENTRANK(N$4:N$91,N12))*100,"") -> 23.3 | AN12: =IFERROR(IF('3 — Weights'!$E$8=1,PERCENTRANK(O$4:O$91,O12),1-PERCENTRANK(O$4:O$91,O12))*100,"") -> 20.4 | AO12: =IFERROR(IF('3 — Weights'!$E$9=1,PERCENTRANK(P$4:P$91,P12),1-PERCENTRANK(P$4:P$91,P12))*100,"") -> 45.8 | AP12: =IFERROR(IF('3 — Weights'!$E$10=1,PERCENTRANK(Q$4:Q$91,Q12),1-PERCENTRANK(Q$4:Q$91,Q12))*100,"") -> 96.4 | AQ12: =IFERROR(IF('3 — Weights'!$E$11=1,PERCENTRANK(R$4:R$91,R12),1-PERCENTRANK(R$4:R$91,R12))*100,"") -> 0 | AR12: =IFERROR(IF('3 — Weights'!$E$12=1,PERCENTRANK(S$4:S$91,S12),1-PERCENTRANK(S$4:S$91,S12))*100,"") -> 86.4 | AS12: =IFERROR(IF('3 — Weights'!$E$13=1,PERCENTRANK(T$4:T$91,T12),1-PERCENTRANK(T$4:T$91,T12))*100,"") -> 81.9 | AT12: =IFERROR(IF('3 — Weights'!$E$14=1,PERCENTRANK(U$4:U$91,U12),1-PERCENTRANK(U$4:U$91,U12))*100,"") -> 23.1 | AU12: =IFERROR(IF('3 — Weights'!$E$15=1,PERCENTRANK(V$4:V$91,V12),1-PERCENTRANK(V$4:V$91,V12))*100,"") -> 95.5 | AV12: =IFERROR(IF('3 — Weights'!$E$16=1,PERCENTRANK(W$4:W$91,W12),1-PERCENTRANK(W$4:W$91,W12))*100,"") -> 94.3 | AW12: =IFERROR(IF('3 — Weights'!$E$17=1,PERCENTRANK(X$4:X$91,X12),1-PERCENTRANK(X$4:X$91,X12))*100,"") -> 96.6 | AX12: =IFERROR(IF('3 — Weights'!$E$18=1,PERCENTRANK(Y$4:Y$91,Y12),1-PERCENTRANK(Y$4:Y$91,Y12))*100,"") -> 89.6 | AY12: =IFERROR(IF('3 — Weights'!$E$18=1,PERCENTRANK(Z$4:Z$91,Z12),1-PERCENTRANK(Z$4:Z$91,Z12))*100,"") -> 80.5 | AZ12: =IFERROR(IF('3 — Weights'!$E$18=1,PERCENTRANK(AA$4:AA$91,AA12),1-PERCENTRANK(AA$4:AA$91,AA12))*100,"") -> 61.7 | BA12: =IFERROR(IF('3 — Weights'!$E$21=1,PERCENTRANK(AB$4:AB$91,AB12),1-PERCENTRANK(AB$4:AB$91,AB12))*100,"") -> 19.5 | BB12: =IFERROR(IF('3 — Weights'!$E$22=1,PERCENTRANK(AC$4:AC$91,AC12),1-PERCENTRANK(AC$4:AC$91,AC12))*100,"") -> 73.5 | BC12: =IFERROR(IF('3 — Weights'!$E$23=1,PERCENTRANK(AD$4:AD$91,AD12),1-PERCENTRANK(AD$4:AD$91,AD12))*100,"") -> 55.2 | BD12: =IFERROR(IF('3 — Weights'!$E$24=1,PERCENTRANK(AE$4:AE$91,AE12),1-PERCENTRANK(AE$4:AE$91,AE12))*100,"") -> 65.6 | BE12: =IFERROR(IF('3 — Weights'!$E$25=1,PERCENTRANK(AF$4:AF$91,AF12),1-PERCENTRANK(AF$4:AF$91,AF12))*100,"") -> 74.8 | BF12: {=IFERROR(SUMPRODUCT(TRANSPOSE(AH12:BE12), [1]!Table2[Weight Claude]),"")} -> 60.215 | BG12: {=IFERROR(SUMPRODUCT(TRANSPOSE(AH12:BE12), [1]!Table2[Weight Cape IMC]),"")} -> 60.215
